Workbook

Sheet Scorecard
A1: Outliers | B1: 46023 | C1: 46054 | D1: 46082 | E1: 46113 | F1: 46143 | G1: 46174 | H1: 46204 | I1: 46235 | J1: 46266 | K1: 46296 | L1: 46327 | M1: 46357 | S1: 46023 | T1: 46054 | U1: 46082 | V1: 46113 | W1: 46143 | X1: 46174 | Y1: 46204 | Z1: 46235 | AA1: 46266 | AB1: 46296 | AC1: 46327 | AD1: 46357 | AE1: 46023 | AF1: 46023 | AG1: 46023 | AH1: 46054 | AI1: 46082 | AJ1: 46113 | AK1: 46143 | AL1: 46174 | AM1: 46204 | AN1: 46235 | AO1: 46266 | AP1: 46296 | AQ1: 46327 | AR1: 46357 | AS1: 46023 | AT1: 46023 | AU1: 46023 | AV1: 46054 | AW1: 46082 | AX1: 46113 | AY1: 46143 | AZ1: 46174 | BA1: 46204 | BB1: 46235 | BC1: 46266 | BD1: 46296 | BE1: 46327 | BF1: 46357 | BG1: 46023 | BH1: 46023 | BI1: 46023 | BJ1: 46054 | BK1: 46082 | BL1: 46113 | BM1: 46143 | BN1: 46174 | BO1: 46204 | BP1: 46235 | BQ1: 46266 | BR1: 46296 | BS1: 46327 | BT1: 46357 | BU1: 46023 | BV1: 46023 | BW1: 46023 | BX1: 46113 | BY1: 46204 | BZ1: 46296 | CC1: 46023
A2: {=_xlfn.QUARTILE.INC(IF(Base!$V:$V>0,Base!$V:$V),3)+(1.5*(_xlfn.QUARTILE.INC(IF(Base!$V:$V>0,Base!$V:$V),3)-_xlfn.QUARTILE.INC(IF(Base!$V:$V>0,Base!$V:$V),1)))} -> 17 | B2: 46053 | C2: 46081 | D2: 46112 | E2: 46142 | F2: 46173 | G2: 46203 | H2: 46234 | I2: 46265 | J2: 46295 | K2: 46326 | L2: 46356 | M2: 46387 | S2: 46053 | T2: 46081 | U2: 46112 | V2: 46142 | W2: 46173 | X2: 46203 | Y2: 46234 | Z2: 46265 | AA2: 46295 | AB2: 46326 | AC2: 46356 | AD2: 46387 | AE2: 46112 | AF2: 46112 | AG2: 46053 | AH2: 46081 | AI2: 46112 | AJ2: 46142 | AK2: 46173 | AL2: 46203 | AM2: 46234 | AN2: 46265 | AO2: 46295 | AP2: 46326 | AQ2: 46356 | AR2: 46387 | AS2: 46112 | AT2: 46112 | AU2: 46053 | AV2: 46081 | AW2: 46112 | AX2: 46142 | AY2: 46173 | AZ2: 46203 | BA2: 46234 | BB2: 46265 | BC2: 46295 | BD2: 46326 | BE2: 46356 | BF2: 46387 | BG2: 46112 | BH2: 46112 | BI2: 46053 | BJ2: 46081 | BK2: 46112 | BL2: 46142 | BM2: 46173 | BN2: 46203 | BO2: 46234 | BP2: 46265 | BQ2: 46295 | BR2: 46326 | BS2: 46356 | BT2: 46387 | BU2: 46112 | BV2: 46112 | BW2: 46112 | BX2: 46203 | BY2: 46295 | BZ2: 41274 | CC2: 46112
AE4: Growth Levers (80%) | BW4: SP Satisfaction (20%)
A5: OM | B5: Jan | C5: Fev | D5: Mar | E5: Apr | F5: May | G5: Jun | H5: Jul | I5: Aug | J5: Sep | K5: Oct | L5: Nov | M5: Dec | N5: Managed SPs | O5: #survey Q1 | P5: # survey Q2 | Q5: # survey Q3 | R5: # survey Q4 | S5: Jan | T5: Fev | U5: Mar | V5: Apr | W5: May | X5: Jun | Y5: Jul | Z5: Aug | AA5: Sep | AB5: Oct | AC5: Nov | AD5: Dec | AE5: Adoption Real | AF5: Nota Adoption | AG5: Jan | AH5: Fev | AI5: Mar | AJ5: Apr | AK5: May | AL5: Jun | AM5: Jul | AN5: Aug | AO5: Sep | AP5: Oct | AQ5: Nov | AR5: Dec | AS5: TTR Real | AT5: Nota TTR | AU5: Jan | AV5: Fev | AW5: Mar | AX5: Apr | AY5: May | AZ5: Jun | BA5: Jul | BB5: Aug | BC5: Sep | BD5: Oct | BE5: Nov | BF5: Dec | BG5: Issue % real | BH5: Nota Issue % | BI5: Jan | BJ5: Fev | BK5: Mar | BL5: Apr | BM5: May | BN5: Jun | BO5: Jul | BP5: Aug | BQ5: Sep | BR5: Oct | BS5: Nov | BT5: Dec | BU5: Strikes | BV5: Nota strikes | BW5: Q1 | BX5: Q2 | BY5: Q3 | BZ5: Q4 | CA5: Survey real | CB5: Nota Survey | CC5: Final Score
A6: fpereluc | B6: =COUNTIFS('Sellers Pro'!$F:$F,Scorecard!$A6,'Sellers Pro'!$Q:$Q,"<"&Scorecard!B$2,'Sellers Pro'!$O:$O,"1") -> 46 | C6: =COUNTIFS('Sellers Pro'!$F:$F,Scorecard!$A6,'Sellers Pro'!$Q:$Q,"<"&Scorecard!C$2,'Sellers Pro'!$O:$O,"1") -> 48 | D6: =COUNTIFS('Sellers Pro'!$F:$F,Scorecard!$A6,'Sellers Pro'!$Q:$Q,"<"&Scorecard!D$2,'Sellers Pro'!$O:$O,"1") -> 48 | E6: =COUNTIFS('Sellers Pro'!$F:$F,Scorecard!$A6,'Sellers Pro'!$Q:$Q,"<"&Scorecard!E$2,'Sellers Pro'!$O:$O,"1") -> 48 | F6: =COUNTIFS('Sellers Pro'!$F:$F,Scorecard!$A6,'Sellers Pro'!$Q:$Q,"<"&Scorecard!F$2,'Sellers Pro'!$O:$O,"1") -> 48 | G6: =COUNTIFS('Sellers Pro'!$F:$F,Scorecard!$A6,'Sellers Pro'!$Q:$Q,"<"&Scorecard!G$2,'Sellers Pro'!$O:$O,"1") -> 48 | H6: =COUNTIFS('Sellers Pro'!$F:$F,Scorecard!$A6,'Sellers Pro'!$Q:$Q,"<"&Scorecard!H$2,'Sellers Pro'!$O:$O,"1") -> 48 | I6: =COUNTIFS('Sellers Pro'!$F:$F,Scorecard!$A6,'Sellers Pro'!$Q:$Q,"<"&Scorecard!I$2,'Sellers Pro'!$O:$O,"1") -> 48 | ... M6: =COUNTIFS('Sellers Pro'!$F:$F,Scorecard!$A6,'Sellers Pro'!$Q:$Q,"<"&Scorecard!M$2,'Sellers Pro'!$O:$O,"1") -> 48 | N6: =IFERROR(AVERAGEIF(B6:M6,">0",B6:M6),"-") -> 47.833333 | O6: =COUNTIFS('Survey Q1'!$G:$G,"="&1,'Survey Q1'!$C:$C,Scorecard!$A6) -> 10 | P6: =COUNTIFS('Survey Q2'!$G:$G,"="&1,'Survey Q1'!$C:$C,Scorecard!$A6) -> 0 | Q6: =COUNTIFS('Survey Q3'!$G:$G,"="&1,'Survey Q1'!$C:$C,Scorecard!$A6) -> 0 | R6: =COUNTIFS('Survey Q4'!$G:$G,"="&1,'Survey Q1'!$C:$C,Scorecard!$A6) -> 0 | S6: =IFERROR(COUNTIFS(Base!$J:$J,Scorecard!$A6,Base!$E:$E,">"&S$1,Base!$E:$E,"<"&S$2,Base!$AH:$AH,"1",Base!$A:$A,"2026")/$N6,"0") -> 0.48083624 | T6: =IFERROR(COUNTIFS(Base!$J:$J,Scorecard!$A6,Base!$E:$E,">"&T$1,Base!$E:$E,"<"&T$2,Base!$AH:$AH,"1",Base!$A:$A,"2026")/$N6,"0") -> 0.68989547 | U6: =IFERROR(COUNTIFS(Base!$J:$J,Scorecard!$A6,Base!$E:$E,">"&U$1,Base!$E:$E,"<"&U$2,Base!$AH:$AH,"1",Base!$A:$A,"2026")/$N6,"0") -> 0.58536585 | V6: =IFERROR(COUNTIFS(Base!$J:$J,Scorecard!$A6,Base!$E:$E,">"&V$1,Base!$E:$E,"<"&V$2,Base!$AH:$AH,"1",Base!$A:$A,"2026")/$N6,"0") -> 0 | W6: =IFERROR(COUNTIFS(Base!$J:$J,Scorecard!$A6,Base!$E:$E,">"&W$1,Base!$E:$E,"<"&W$2,Base!$AH:$AH,"1",Base!$A:$A,"2026")/$N6,"0") -> 0 | X6: =IFERROR(COUNTIFS(Base!$J:$J,Scorecard!$A6,Base!$E:$E,">"&X$1,Base!$E:$E,"<"&X$2,Base!$AH:$AH,"1",Base!$A:$A,"2026")/$N6,"0") -> 0 | Y6: =IFERROR(COUNTIFS(Base!$J:$J,Scorecard!$A6,Base!$E:$E,">"&Y$1,Base!$E:$E,"<"&Y$2,Base!$AH:$AH,"1",Base!$A:$A,"2026")/$N6,"0") -> 0 | Z6: =IFERROR(COUNTIFS(Base!$J:$J,Scorecard!$A6,Base!$E:$E,">"&Z$1,Base!$E:$E,"<"&Z$2,Base!$AH:$AH,"1",Base!$A:$A,"2026")/$N6,"0") -> 0 | ... AD6: =IFERROR(COUNTIFS(Base!$J:$J,Scorecard!$A6,Base!$E:$E,">"&AD$1,Base!$E:$E,"<"&AD$2,Base!$AH:$AH,"1",Base!$A:$A,"2026")/$N6,"0") -> 0 | AE6: =IFERROR(AVERAGEIF(S6:AD6,">0",S6:AD6),"-") -> 0.58536585 | AF6: =IF(AE6="-",0,IF(AE6<Goals!$K$6,Goals!$L$7,IF(AE6<Goals!$K$5,Goals!$L$6,IF(AE6<Goals!$K$4,Goals!$L$5,IF(AE6<Goals!$K$3,Goals!$L$4,IF(AE6<Goals!$K$2,Goals!$L$3,Goals!$L$2)))))) -> 0.5 | AG6: =IFERROR(AVERAGEIFS(Base!$V:$V,Base!$J:$J,Scorecard!$A6,Base!$E:$E,">"&AG$1,Base!$G:$G,"<"&AG$2,Base!$V:$V,"<"&$A$2,Base!$V:$V,">"&0,Base!$A:$A,"2026"),"0") -> 3.25 | AH6: =IFERROR(AVERAGEIFS(Base!$V:$V,Base!$J:$J,Scorecard!$A6,Base!$E:$E,">"&AH$1,Base!$G:$G,"<"&AH$2,Base!$V:$V,"<"&$A$2,Base!$V:$V,">"&0,Base!$A:$A,"2026"),"0") -> 4.859375 | AI6: =IFERROR(AVERAGEIFS(Base!$V:$V,Base!$J:$J,Scorecard!$A6,Base!$E:$E,">"&AI$1,Base!$G:$G,"<"&AI$2,Base!$V:$V,"<"&$A$2,Base!$V:$V,">"&0,Base!$A:$A,"2026"),"0") -> 3.2678571 | AJ6: =IFERROR(AVERAGEIFS(Base!$V:$V,Base!$J:$J,Scorecard!$A6,Base!$E:$E,">"&AJ$1,Base!$G:$G,"<"&AJ$2,Base!$V:$V,"<"&$A$2,Base!$V:$V,">"&0,Base!$A:$A,"2026"),"0") -> 0 | AK6: =IFERROR(AVERAGEIFS(Base!$V:$V,Base!$J:$J,Scorecard!$A6,Base!$E:$E,">"&AK$1,Base!$G:$G,"<"&AK$2,Base!$V:$V,"<"&$A$2,Base!$V:$V,">"&0,Base!$A:$A,"2026"),"0") -> 0 | AL6: =IFERROR(AVERAGEIFS(Base!$V:$V,Base!$J:$J,Scorecard!$A6,Base!$E:$E,">"&AL$1,Base!$G:$G,"<"&AL$2,Base!$V:$V,"<"&$A$2,Base!$V:$V,">"&0,Base!$A:$A,"2026"),"0") -> 0 | AM6: =IFERROR(AVERAGEIFS(Base!$V:$V,Base!$J:$J,Scorecard!$A6,Base!$E:$E,">"&AM$1,Base!$G:$G,"<"&AM$2,Base!$V:$V,"<"&$A$2,Base!$V:$V,">"&0,Base!$A:$A,"2026"),"0") -> 0 | AN6: =IFERROR(AVERAGEIFS(Base!$V:$V,Base!$J:$J,Scorecard!$A6,Base!$E:$E,">"&AN$1,Base!$G:$G,"<"&AN$2,Base!$V:$V,"<"&$A$2,Base!$V:$V,">"&0,Base!$A:$A,"2026"),"0") -> 0 | ... AR6: =IFERROR(AVERAGEIFS(Base!$V:$V,Base!$J:$J,Scorecard!$A6,Base!$E:$E,">"&AR$1,Base!$G:$G,"<"&AR$2,Base!$V:$V,"<"&$A$2,Base!$V:$V,">"&0,Base!$A:$A,"2026"),"0") -> 0 | AS6: =IFERROR(AVERAGEIF(AG6:AR6,">0",AG6:AR6),"-") -> 3.7924107 | AT6: =IF(AS6="-",0,IF(AS6>Goals!$N$6,Goals!$O$7,IF(AS6>Goals!$N$5,Goals!$O$6,IF(AS6>Goals!$N$4,Goals!$O$5,IF(AS6>Goals!$N$3,Goals!$O$4,IF(AS6>Goals!$N$2,Goals!$O$3,Goals!$O$2)))))) -> 0.8 | AU6: =IFERROR(COUNTIFS(Base!$E:$E,">"&AU$1,Base!$G:$G,"<"&AU$2,Base!$J:$J,Scorecard!$A6,Base!$T:$T,"COMPLETED")/COUNTIFS(Base!$E:$E,">"&AU$1,Base!$E:$E,"<"&AU$2,Base!$J:$J,Scorecard!$A6),"0") -> 0.7 | AV6: =IFERROR(COUNTIFS(Base!$E:$E,">"&AV$1,Base!$G:$G,"<"&AV$2,Base!$J:$J,Scorecard!$A6,Base!$T:$T,"COMPLETED")/COUNTIFS(Base!$E:$E,">"&AV$1,Base!$E:$E,"<"&AV$2,Base!$J:$J,Scorecard!$A6),"0") -> 0.71875 | AW6: =IFERROR(COUNTIFS(Base!$E:$E,">"&AW$1,Base!$G:$G,"<"&AW$2,Base!$J:$J,Scorecard!$A6,Base!$T:$T,"COMPLETED")/COUNTIFS(Base!$E:$E,">"&AW$1,Base!$E:$E,"<"&AW$2,Base!$J:$J,Scorecard!$A6),"0") -> 0.68181818 | AX6: =IFERROR(COUNTIFS(Base!$E:$E,">"&AX$1,Base!$G:$G,"<"&AX$2,Base!$J:$J,Scorecard!$A6,Base!$T:$T,"COMPLETED")/COUNTIFS(Base!$E:$E,">"&AX$1,Base!$E:$E,"<"&AX$2,Base!$J:$J,Scorecard!$A6),"0") -> 0 | AY6: =IFERROR(COUNTIFS(Base!$E:$E,">"&AY$1,Base!$G:$G,"<"&AY$2,Base!$J:$J,Scorecard!$A6,Base!$T:$T,"COMPLETED")/COUNTIFS(Base!$E:$E,">"&AY$1,Base!$E:$E,"<"&AY$2,Base!$J:$J,Scorecard!$A6),"0") -> 0 | AZ6: =IFERROR(COUNTIFS(Base!$E:$E,">"&AZ$1,Base!$G:$G,"<"&AZ$2,Base!$J:$J,Scorecard!$A6,Base!$T:$T,"COMPLETED")/COUNTIFS(Base!$E:$E,">"&AZ$1,Base!$E:$E,"<"&AZ$2,Base!$J:$J,Scorecard!$A6),"0") -> 0 | BA6: =IFERROR(COUNTIFS(Base!$E:$E,">"&BA$1,Base!$G:$G,"<"&BA$2,Base!$J:$J,Scorecard!$A6,Base!$T:$T,"COMPLETED")/COUNTIFS(Base!$E:$E,">"&BA$1,Base!$E:$E,"<"&BA$2,Base!$J:$J,Scorecard!$A6),"0") -> 0 | BB6: =IFERROR(COUNTIFS(Base!$E:$E,">"&BB$1,Base!$G:$G,"<"&BB$2,Base!$J:$J,Scorecard!$A6,Base!$T:$T,"COMPLETED")/COUNTIFS(Base!$E:$E,">"&BB$1,Base!$E:$E,"<"&BB$2,Base!$J:$J,Scorecard!$A6),"0") -> 0 | ... BF6: =IFERROR(COUNTIFS(Base!$E:$E,">"&BF$1,Base!$G:$G,"<"&BF$2,Base!$J:$J,Scorecard!$A6,Base!$T:$T,"COMPLETED")/COUNTIFS(Base!$E:$E,">"&BF$1,Base!$E:$E,"<"&BF$2,Base!$J:$J,Scorecard!$A6),"0") -> 0 | BG6: =IFERROR(AVERAGEIF(AU6:BF6,">0",AU6:BF6),"-") -> 0.70018939 | BH6: =IF(BG6="-",0,IF(BG6<Goals!$Q$6,Goals!$R$7,IF(BG6<Goals!$Q$5,Goals!$R$6,IF(BG6<Goals!$Q$4,Goals!$R$5,IF(BG6<Goals!$Q$3,Goals!$R$4,IF(BG6<Goals!$Q$2,Goals!$R$3,Goals!$R$2)))))) -> 0.5 | BI6: =COUNTIFS(Strikes!$A:$A,Scorecard!$A6,Strikes!$C:$C,">"&Scorecard!BI$1,Strikes!$C:$C,"<"&Scorecard!BI$2) -> 0 | BJ6: =COUNTIFS(Strikes!$A:$A,Scorecard!$A6,Strikes!$C:$C,">"&Scorecard!BJ$1,Strikes!$C:$C,"<"&Scorecard!BJ$2) -> 0 | BK6: =COUNTIFS(Strikes!$A:$A,Scorecard!$A6,Strikes!$C:$C,">"&Scorecard!BK$1,Strikes!$C:$C,"<"&Scorecard!BK$2) -> 0 | BL6: =COUNTIFS(Strikes!$A:$A,Scorecard!$A6,Strikes!$C:$C,">"&Scorecard!BL$1,Strikes!$C:$C,"<"&Scorecard!BL$2) -> 0 | BM6: =COUNTIFS(Strikes!$A:$A,Scorecard!$A6,Strikes!$C:$C,">"&Scorecard!BM$1,Strikes!$C:$C,"<"&Scorecard!BM$2) -> 0 | BN6: =COUNTIFS(Strikes!$A:$A,Scorecard!$A6,Strikes!$C:$C,">"&Scorecard!BN$1,Strikes!$C:$C,"<"&Scorecard!BN$2) -> 0 | BO6: =COUNTIFS(Strikes!$A:$A,Scorecard!$A6,Strikes!$C:$C,">"&Scorecard!BO$1,Strikes!$C:$C,"<"&Scorecard!BO$2) -> 0 | BP6: =COUNTIFS(Strikes!$A:$A,Scorecard!$A6,Strikes!$C:$C,">"&Scorecard!BP$1,Strikes!$C:$C,"<"&Scorecard!BP$2) -> 0 | ... BT6: =COUNTIFS(Strikes!$A:$A,Scorecard!$A6,Strikes!$C:$C,">"&Scorecard!BT$1,Strikes!$C:$C,"<"&Scorecard!BT$2) -> 0 | BU6: =IFERROR(AVERAGEIF(BI6:BT6,">0",BI6:BT6),"0") -> 0 | BV6: =IF(BU6="-",0,IF(BU6=Goals!$H$7,Goals!$I$7,IF(BU6=Goals!$H$6,Goals!$I$6,IF(BU6=Goals!$H$5,Goals!$I$5,IF(BU6=Goals!$H$4,Goals!$I$4,IF(BU6=Goals!$H$3,Goals!$I$3,Goals!$I$2)))))) -> 1.2 | BW6: =IFERROR(COUNTIFS('Survey Q1'!$C:$C,Scorecard!$A6,'Survey Q1'!$F:$F,"1")/O6,"0") -> 0.7 | BX6: =IFERROR(COUNTIFS('Survey Q2'!$C:$C,Scorecard!$A6,'Survey Q1'!$F:$F,"1")/P6,"0") -> 0 | BY6: =IFERROR(COUNTIFS('Survey Q3'!$C:$C,Scorecard!$A6,'Survey Q1'!$F:$F,"1")/Q6,"0") -> 0 | BZ6: =IFERROR(COUNTIFS('Survey Q4'!$C:$C,Scorecard!$A6,'Survey Q1'!$F:$F,"1")/R6,"0") -> 0 | CA6: =IFERROR(AVERAGEIF(BW6:BZ6,">0",BW6:BZ6),"-") -> 0.7 | CB6: =IF(CA6="-",0,IF(CA6<Goals!$T$6,Goals!$U$7,IF(CA6<Goals!$T$5,Goals!$U$6,IF(CA6<Goals!$T$4,Goals!$U$5,IF(CA6<Goals!$T$3,Goals!$U$4,IF(CA6<Goals!$T$2,Goals!$U$3,Goals!$U$2)))))) -> 0 | CC6: =Scorecard!AF6*Goals!$C$3+Scorecard!AT6*Goals!$D$3+Scorecard!BH6*Goals!$E$3+Scorecard!CB6*Goals!$B$3+BV6*Goals!$F$3 -> 0.51
A7: gomrodrd | B7: =COUNTIFS('Sellers Pro'!$F:$F,Scorecard!$A7,'Sellers Pro'!$Q:$Q,"<"&Scorecard!B$2,'Sellers Pro'!$O:$O,"1") -> 39 | C7: =COUNTIFS('Sellers Pro'!$F:$F,Scorecard!$A7,'Sellers Pro'!$Q:$Q,"<"&Scorecard!C$2,'Sellers Pro'!$O:$O,"1") -> 39 | D7: =COUNTIFS('Sellers Pro'!$F:$F,Scorecard!$A7,'Sellers Pro'!$Q:$Q,"<"&Scorecard!D$2,'Sellers Pro'!$O:$O,"1") -> 39 | E7: =COUNTIFS('Sellers Pro'!$F:$F,Scorecard!$A7,'Sellers Pro'!$Q:$Q,"<"&Scorecard!E$2,'Sellers Pro'!$O:$O,"1") -> 39 | F7: =COUNTIFS('Sellers Pro'!$F:$F,Scorecard!$A7,'Sellers Pro'!$Q:$Q,"<"&Scorecard!F$2,'Sellers Pro'!$O:$O,"1") -> 39 | G7: =COUNTIFS('Sellers Pro'!$F:$F,Scorecard!$A7,'Sellers Pro'!$Q:$Q,"<"&Scorecard!G$2,'Sellers Pro'!$O:$O,"1") -> 39 | H7: =COUNTIFS('Sellers Pro'!$F:$F,Scorecard!$A7,'Sellers Pro'!$Q:$Q,"<"&Scorecard!H$2,'Sellers Pro'!$O:$O,"1") -> 39 | I7: =COUNTIFS('Sellers Pro'!$F:$F,Scorecard!$A7,'Sellers Pro'!$Q:$Q,"<"&Scorecard!I$2,'Sellers Pro'!$O:$O,"1") -> 39 | ... M7: =COUNTIFS('Sellers Pro'!$F:$F,Scorecard!$A7,'Sellers Pro'!$Q:$Q,"<"&Scorecard!M$2,'Sellers Pro'!$O:$O,"1") -> 39 | N7: =IFERROR(AVERAGEIF(B7:M7,">0",B7:M7),"-") -> 39 | O7: =COUNTIFS('Survey Q1'!$G:$G,"="&1,'Survey Q1'!$C:$C,Scorecard!$A7) -> 19 | P7: =COUNTIFS('Survey Q2'!$G:$G,"="&1,'Survey Q1'!$C:$C,Scorecard!$A7) -> 0 | Q7: =COUNTIFS('Survey Q3'!$G:$G,"="&1,'Survey Q1'!$C:$C,Scorecard!$A7) -> 0 | R7: =COUNTIFS('Survey Q4'!$G:$G,"="&1,'Survey Q1'!$C:$C,Scorecard!$A7) -> 0 | S7: =IFERROR(COUNTIFS(Base!$J:$J,Scorecard!$A7,Base!$E:$E,">"&S$1,Base!$E:$E,"<"&S$2,Base!$AH:$AH,"1",Base!$A:$A,"2026")/$N7,"0") -> 0.64102564 | T7: =IFERROR(COUNTIFS(Base!$J:$J,Scorecard!$A7,Base!$E:$E,">"&T$1,Base!$E:$E,"<"&T$2,Base!$AH:$AH,"1",Base!$A:$A,"2026")/$N7,"0") -> 0.53846154 | U7: =IFERROR(COUNTIFS(Base!$J:$J,Scorecard!$A7,Base!$E:$E,">"&U$1,Base!$E:$E,"<"&U$2,Base!$AH:$AH,"1",Base!$A:$A,"2026")/$N7,"0") -> 0.66666667 | V7: =IFERROR(COUNTIFS(Base!$J:$J,Scorecard!$A7,Base!$E:$E,">"&V$1,Base!$E:$E,"<"&V$2,Base!$AH:$AH,"1",Base!$A:$A,"2026")/$N7,"0") -> 0 | W7: =IFERROR(COUNTIFS(Base!$J:$J,Scorecard!$A7,Base!$E:$E,">"&W$1,Base!$E:$E,"<"&W$2,Base!$AH:$AH,"1",Base!$A:$A,"2026")/$N7,"0") -> 0 | X7: =IFERROR(COUNTIFS(Base!$J:$J,Scorecard!$A7,Base!$E:$E,">"&X$1,Base!$E:$E,"<"&X$2,Base!$AH:$AH,"1",Base!$A:$A,"2026")/$N7,"0") -> 0 | Y7: =IFERROR(COUNTIFS(Base!$J:$J,Scorecard!$A7,Base!$E:$E,">"&Y$1,Base!$E:$E,"<"&Y$2,Base!$AH:$AH,"1",Base!$A:$A,"2026")/$N7,"0") -> 0 | Z7: =IFERROR(COUNTIFS(Base!$J:$J,Scorecard!$A7,Base!$E:$E,">"&Z$1,Base!$E:$E,"<"&Z$2,Base!$AH:$AH,"1",Base!$A:$A,"2026")/$N7,"0") -> 0 | ... AD7: =IFERROR(COUNTIFS(Base!$J:$J,Scorecard!$A7,Base!$E:$E,">"&AD$1,Base!$E:$E,"<"&AD$2,Base!$AH:$AH,"1",Base!$A:$A,"2026")/$N7,"0") -> 0 | AE7: =IFERROR(AVERAGEIF(S7:AD7,">0",S7:AD7),"-") -> 0.61538462 | AF7: =IF(AE7="-",0,IF(AE7<Goals!$K$6,Goals!$L$7,IF(AE7<Goals!$K$5,Goals!$L$6,IF(AE7<Goals!$K$4,Goals!$L$5,IF(AE7<Goals!$K$3,Goals!$L$4,IF(AE7<Goals!$K$2,Goals!$L$3,Goals!$L$2)))))) -> 0.5 | AG7: =IFERROR(AVERAGEIFS(Base!$V:$V,Base!$J:$J,Scorecard!$A7,Base!$E:$E,">"&AG$1,Base!$G:$G,"<"&AG$2,Base!$V:$V,"<"&$A$2,Base!$V:$V,">"&0,Base!$A:$A,"2026"),"0") -> 3.6944444 | AH7: =IFERROR(AVERAGEIFS(Base!$V:$V,Base!$J:$J,Scorecard!$A7,Base!$E:$E,">"&AH$1,Base!$G:$G,"<"&AH$2,Base!$V:$V,"<"&$A$2,Base!$V:$V,">"&0,Base!$A:$A,"2026"),"0") -> 3.2142857 | AI7: =IFERROR(AVERAGEIFS(Base!$V:$V,Base!$J:$J,Scorecard!$A7,Base!$E:$E,">"&AI$1,Base!$G:$G,"<"&AI$2,Base!$V:$V,"<"&$A$2,Base!$V:$V,">"&0,Base!$A:$A,"2026"),"0") -> 3.075 | AJ7: =IFERROR(AVERAGEIFS(Base!$V:$V,Base!$J:$J,Scorecard!$A7,Base!$E:$E,">"&AJ$1,Base!$G:$G,"<"&AJ$2,Base!$V:$V,"<"&$A$2,Base!$V:$V,">"&0,Base!$A:$A,"2026"),"0") -> 0 | AK7: =IFERROR(AVERAGEIFS(Base!$V:$V,Base!$J:$J,Scorecard!$A7,Base!$E:$E,">"&AK$1,Base!$G:$G,"<"&AK$2,Base!$V:$V,"<"&$A$2,Base!$V:$V,">"&0,Base!$A:$A,"2026"),"0") -> 0 | AL7: =IFERROR(AVERAGEIFS(Base!$V:$V,Base!$J:$J,Scorecard!$A7,Base!$E:$E,">"&AL$1,Base!$G:$G,"<"&AL$2,Base!$V:$V,"<"&$A$2,Base!$V:$V,">"&0,Base!$A:$A,"2026"),"0") -> 0 | AM7: =IFERROR(AVERAGEIFS(Base!$V:$V,Base!$J:$J,Scorecard!$A7,Base!$E:$E,">"&AM$1,Base!$G:$G,"<"&AM$2,Base!$V:$V,"<"&$A$2,Base!$V:$V,">"&0,Base!$A:$A,"2026"),"0") -> 0 | AN7: =IFERROR(AVERAGEIFS(Base!$V:$V,Base!$J:$J,Scorecard!$A7,Base!$E:$E,">"&AN$1,Base!$G:$G,"<"&AN$2,Base!$V:$V,"<"&$A$2,Base!$V:$V,">"&0,Base!$A:$A,"2026"),"0") -> 0 | ... AR7: =IFERROR(AVERAGEIFS(Base!$V:$V,Base!$J:$J,Scorecard!$A7,Base!$E:$E,">"&AR$1,Base!$G:$G,"<"&AR$2,Base!$V:$V,"<"&$A$2,Base!$V:$V,">"&0,Base!$A:$A,"2026"),"0") -> 0 | AS7: =IFERROR(AVERAGEIF(AG7:AR7,">0",AG7:AR7),"-") -> 3.3279101 | AT7: =IF(AS7="-",0,IF(AS7>Goals!$N$6,Goals!$O$7,IF(AS7>Goals!$N$5,Goals!$O$6,IF(AS7>Goals!$N$4,Goals!$O$5,IF(AS7>Goals!$N$3,Goals!$O$4,IF(AS7>Goals!$N$2,Goals!$O$3,Goals!$O$2)))))) -> 0.8 | AU7: =IFERROR(COUNTIFS(Base!$E:$E,">"&AU$1,Base!$G:$G,"<"&AU$2,Base!$J:$J,Scorecard!$A7,Base!$T:$T,"COMPLETED")/COUNTIFS(Base!$E:$E,">"&AU$1,Base!$E:$E,"<"&AU$2,Base!$J:$J,Scorecard!$A7),"0") -> 0.75 | AV7: =IFERROR(COUNTIFS(Base!$E:$E,">"&AV$1,Base!$G:$G,"<"&AV$2,Base!$J:$J,Scorecard!$A7,Base!$T:$T,"COMPLETED")/COUNTIFS(Base!$E:$E,">"&AV$1,Base!$E:$E,"<"&AV$2,Base!$J:$J,Scorecard!$A7),"0") -> 0.72580645 | AW7: =IFERROR(COUNTIFS(Base!$E:$E,">"&AW$1,Base!$G:$G,"<"&AW$2,Base!$J:$J,Scorecard!$A7,Base!$T:$T,"COMPLETED")/COUNTIFS(Base!$E:$E,">"&AW$1,Base!$E:$E,"<"&AW$2,Base!$J:$J,Scorecard!$A7),"0") -> 0.65909091 | AX7: =IFERROR(COUNTIFS(Base!$E:$E,">"&AX$1,Base!$G:$G,"<"&AX$2,Base!$J:$J,Scorecard!$A7,Base!$T:$T,"COMPLETED")/COUNTIFS(Base!$E:$E,">"&AX$1,Base!$E:$E,"<"&AX$2,Base!$J:$J,Scorecard!$A7),"0") -> 0 | AY7: =IFERROR(COUNTIFS(Base!$E:$E,">"&AY$1,Base!$G:$G,"<"&AY$2,Base!$J:$J,Scorecard!$A7,Base!$T:$T,"COMPLETED")/COUNTIFS(Base!$E:$E,">"&AY$1,Base!$E:$E,"<"&AY$2,Base!$J:$J,Scorecard!$A7),"0") -> 0 | AZ7: =IFERROR(COUNTIFS(Base!$E:$E,">"&AZ$1,Base!$G:$G,"<"&AZ$2,Base!$J:$J,Scorecard!$A7,Base!$T:$T,"COMPLETED")/COUNTIFS(Base!$E:$E,">"&AZ$1,Base!$E:$E,"<"&AZ$2,Base!$J:$J,Scorecard!$A7),"0") -> 0 | BA7: =IFERROR(COUNTIFS(Base!$E:$E,">"&BA$1,Base!$G:$G,"<"&BA$2,Base!$J:$J,Scorecard!$A7,Base!$T:$T,"COMPLETED")/COUNTIFS(Base!$E:$E,">"&BA$1,Base!$E:$E,"<"&BA$2,Base!$J:$J,Scorecard!$A7),"0") -> 0 | BB7: =IFERROR(COUNTIFS(Base!$E:$E,">"&BB$1,Base!$G:$G,"<"&BB$2,Base!$J:$J,Scorecard!$A7,Base!$T:$T,"COMPLETED")/COUNTIFS(Base!$E:$E,">"&BB$1,Base!$E:$E,"<"&BB$2,Base!$J:$J,Scorecard!$A7),"0") -> 0 | ... BF7: =IFERROR(COUNTIFS(Base!$E:$E,">"&BF$1,Base!$G:$G,"<"&BF$2,Base!$J:$J,Scorecard!$A7,Base!$T:$T,"COMPLETED")/COUNTIFS(Base!$E:$E,">"&BF$1,Base!$E:$E,"<"&BF$2,Base!$J:$J,Scorecard!$A7),"0") -> 0 | BG7: =IFERROR(AVERAGEIF(AU7:BF7,">0",AU7:BF7),"-") -> 0.71163245 | BH7: =IF(BG7="-",0,IF(BG7<Goals!$Q$6,Goals!$R$7,IF(BG7<Goals!$Q$5,Goals!$R$6,IF(BG7<Goals!$Q$4,Goals!$R$5,IF(BG7<Goals!$Q$3,Goals!$R$4,IF(BG7<Goals!$Q$2,Goals!$R$3,Goals!$R$2)))))) -> 0.5 | BI7: =COUNTIFS(Strikes!$A:$A,Scorecard!$A7,Strikes!$C:$C,">"&Scorecard!BI$1,Strikes!$C:$C,"<"&Scorecard!BI$2) -> 0 | BJ7: =COUNTIFS(Strikes!$A:$A,Scorecard!$A7,Strikes!$C:$C,">"&Scorecard!BJ$1,Strikes!$C:$C,"<"&Scorecard!BJ$2) -> 1 | BK7: =COUNTIFS(Strikes!$A:$A,Scorecard!$A7,Strikes!$C:$C,">"&Scorecard!BK$1,Strikes!$C:$C,"<"&Scorecard!BK$2) -> 0 | BL7: =COUNTIFS(Strikes!$A:$A,Scorecard!$A7,Strikes!$C:$C,">"&Scorecard!BL$1,Strikes!$C:$C,"<"&Scorecard!BL$2) -> 0 | BM7: =COUNTIFS(Strikes!$A:$A,Scorecard!$A7,Strikes!$C:$C,">"&Scorecard!BM$1,Strikes!$C:$C,"<"&Scorecard!BM$2) -> 0 | BN7: =COUNTIFS(Strikes!$A:$A,Scorecard!$A7,Strikes!$C:$C,">"&Scorecard!BN$1,Strikes!$C:$C,"<"&Scorecard!BN$2) -> 0 | BO7: =COUNTIFS(Strikes!$A:$A,Scorecard!$A7,Strikes!$C:$C,">"&Scorecard!BO$1,Strikes!$C:$C,"<"&Scorecard!BO$2) -> 0 | BP7: =COUNTIFS(Strikes!$A:$A,Scorecard!$A7,Strikes!$C:$C,">"&Scorecard!BP$1,Strikes!$C:$C,"<"&Scorecard!BP$2) -> 0 | ... BT7: =COUNTIFS(Strikes!$A:$A,Scorecard!$A7,Strikes!$C:$C,">"&Scorecard!BT$1,Strikes!$C:$C,"<"&Scorecard!BT$2) -> 0 | BU7: =IFERROR(AVERAGEIF(BI7:BT7,">0",BI7:BT7),"0") -> 1 | BV7: =IF(BU7="-",0,IF(BU7=Goals!$H$7,Goals!$I$7,IF(BU7=Goals!$H$6,Goals!$I$6,IF(BU7=Goals!$H$5,Goals!$I$5,IF(BU7=Goals!$H$4,Goals!$I$4,IF(BU7=Goals!$H$3,Goals!$I$3,Goals!$I$2)))))) -> 1.2 | BW7: =IFERROR(COUNTIFS('Survey Q1'!$C:$C,Scorecard!$A7,'Survey Q1'!$F:$F,"1")/O7,"0") -> 0.89473684 | BX7: =IFERROR(COUNTIFS('Survey Q2'!$C:$C,Scorecard!$A7,'Survey Q1'!$F:$F,"1")/P7,"0") -> 0 | BY7: =IFERROR(COUNTIFS('Survey Q3'!$C:$C,Scorecard!$A7,'Survey Q1'!$F:$F,"1")/Q7,"0") -> 0 | BZ7: =IFERROR(COUNTIFS('Survey Q4'!$C:$C,Scorecard!$A7,'Survey Q1'!$F:$F,"1")/R7,"0") -> 0 | CA7: =IFERROR(AVERAGEIF(BW7:BZ7,">0",BW7:BZ7),"-") -> 0.89473684 | CB7: =IF(CA7="-",0,IF(CA7<Goals!$T$6,Goals!$U$7,IF(CA7<Goals!$T$5,Goals!$U$6,IF(CA7<Goals!$T$4,Goals!$U$5,IF(CA7<Goals!$T$3,Goals!$U$4,IF(CA7<Goals!$T$2,Goals!$U$3,Goals!$U$2)))))) -> 0.8 | CC7: =Scorecard!AF7*Goals!$C$3+Scorecard!AT7*Goals!$D$3+Scorecard!BH7*Goals!$E$3+Scorecard!CB7*Goals!$B$3+BV7*Goals!$F$3 -> 0.67
A8: joaoclan | B8: =COUNTIFS('Sellers Pro'!$F:$F,Scorecard!$A8,'Sellers Pro'!$Q:$Q,"<"&Scorecard!B$2,'Sellers Pro'!$O:$O,"1") -> 33 | C8: =COUNTIFS('Sellers Pro'!$F:$F,Scorecard!$A8,'Sellers Pro'!$Q:$Q,"<"&Scorecard!C$2,'Sellers Pro'!$O:$O,"1") -> 33 | D8: =COUNTIFS('Sellers Pro'!$F:$F,Scorecard!$A8,'Sellers Pro'!$Q:$Q,"<"&Scorecard!D$2,'Sellers Pro'!$O:$O,"1") -> 33 | E8: =COUNTIFS('Sellers Pro'!$F:$F,Scorecard!$A8,'Sellers Pro'!$Q:$Q,"<"&Scorecard!E$2,'Sellers Pro'!$O:$O,"1") -> 33 | F8: =COUNTIFS('Sellers Pro'!$F:$F,Scorecard!$A8,'Sellers Pro'!$Q:$Q,"<"&Scorecard!F$2,'Sellers Pro'!$O:$O,"1") -> 33 | G8: =COUNTIFS('Sellers Pro'!$F:$F,Scorecard!$A8,'Sellers Pro'!$Q:$Q,"<"&Scorecard!G$2,'Sellers Pro'!$O:$O,"1") -> 33 | H8: =COUNTIFS('Sellers Pro'!$F:$F,Scorecard!$A8,'Sellers Pro'!$Q:$Q,"<"&Scorecard!H$2,'Sellers Pro'!$O:$O,"1") -> 33 | I8: =COUNTIFS('Sellers Pro'!$F:$F,Scorecard!$A8,'Sellers Pro'!$Q:$Q,"<"&Scorecard!I$2,'Sellers Pro'!$O:$O,"1") -> 33 | ... M8: =COUNTIFS('Sellers Pro'!$F:$F,Scorecard!$A8,'Sellers Pro'!$Q:$Q,"<"&Scorecard!M$2,'Sellers Pro'!$O:$O,"1") -> 33 | N8: =IFERROR(AVERAGEIF(B8:M8,">0",B8:M8),"-") -> 33 | O8: =COUNTIFS('Survey Q1'!$G:$G,"="&1,'Survey Q1'!$C:$C,Scorecard!$A8) -> 13 | P8: =COUNTIFS('Survey Q2'!$G:$G,"="&1,'Survey Q1'!$C:$C,Scorecard!$A8) -> 0 | Q8: =COUNTIFS('Survey Q3'!$G:$G,"="&1,'Survey Q1'!$C:$C,Scorecard!$A8) -> 0 | R8: =COUNTIFS('Survey Q4'!$G:$G,"="&1,'Survey Q1'!$C:$C,Scorecard!$A8) -> 0 | S8: =IFERROR(COUNTIFS(Base!$J:$J,Scorecard!$A8,Base!$E:$E,">"&S$1,Base!$E:$E,"<"&S$2,Base!$AH:$AH,"1",Base!$A:$A,"2026")/$N8,"0") -> 0.57575758 | T8: =IFERROR(COUNTIFS(Base!$J:$J,Scorecard!$A8,Base!$E:$E,">"&T$1,Base!$E:$E,"<"&T$2,Base!$AH:$AH,"1",Base!$A:$A,"2026")/$N8,"0") -> 0.78787879 | U8: =IFERROR(COUNTIFS(Base!$J:$J,Scorecard!$A8,Base!$E:$E,">"&U$1,Base!$E:$E,"<"&U$2,Base!$AH:$AH,"1",Base!$A:$A,"2026")/$N8,"0") -> 0.57575758 | V8: =IFERROR(COUNTIFS(Base!$J:$J,Scorecard!$A8,Base!$E:$E,">"&V$1,Base!$E:$E,"<"&V$2,Base!$AH:$AH,"1",Base!$A:$A,"2026")/$N8,"0") -> 0 | W8: =IFERROR(COUNTIFS(Base!$J:$J,Scorecard!$A8,Base!$E:$E,">"&W$1,Base!$E:$E,"<"&W$2,Base!$AH:$AH,"1",Base!$A:$A,"2026")/$N8,"0") -> 0 | X8: =IFERROR(COUNTIFS(Base!$J:$J,Scorecard!$A8,Base!$E:$E,">"&X$1,Base!$E:$E,"<"&X$2,Base!$AH:$AH,"1",Base!$A:$A,"2026")/$N8,"0") -> 0 | Y8: =IFERROR(COUNTIFS(Base!$J:$J,Scorecard!$A8,Base!$E:$E,">"&Y$1,Base!$E:$E,"<"&Y$2,Base!$AH:$AH,"1",Base!$A:$A,"2026")/$N8,"0") -> 0 | Z8: =IFERROR(COUNTIFS(Base!$J:$J,Scorecard!$A8,Base!$E:$E,">"&Z$1,Base!$E:$E,"<"&Z$2,Base!$AH:$AH,"1",Base!$A:$A,"2026")/$N8,"0") -> 0 | ... AD8: =IFERROR(COUNTIFS(Base!$J:$J,Scorecard!$A8,Base!$E:$E,">"&AD$1,Base!$E:$E,"<"&AD$2,Base!$AH:$AH,"1",Base!$A:$A,"2026")/$N8,"0") -> 0 | AE8: =IFERROR(AVERAGEIF(S8:AD8,">0",S8:AD8),"-") -> 0.64646465 | AF8: =IF(AE8="-",0,IF(AE8<Goals!$K$6,Goals!$L$7,IF(AE8<Goals!$K$5,Goals!$L$6,IF(AE8<Goals!$K$4,Goals!$L$5,IF(AE8<Goals!$K$3,Goals!$L$4,IF(AE8<Goals!$K$2,Goals!$L$3,Goals!$L$2)))))) -> 0.5 | AG8: =IFERROR(AVERAGEIFS(Base!$V:$V,Base!$J:$J,Scorecard!$A8,Base!$E:$E,">"&AG$1,Base!$G:$G,"<"&AG$2,Base!$V:$V,"<"&$A$2,Base!$V:$V,">"&0,Base!$A:$A,"2026"),"0") -> 3.325 | AH8: =IFERROR(AVERAGEIFS(Base!$V:$V,Base!$J:$J,Scorecard!$A8,Base!$E:$E,">"&AH$1,Base!$G:$G,"<"&AH$2,Base!$V:$V,"<"&$A$2,Base!$V:$V,">"&0,Base!$A:$A,"2026"),"0") -> 4.1136364 | AI8: =IFERROR(AVERAGEIFS(Base!$V:$V,Base!$J:$J,Scorecard!$A8,Base!$E:$E,">"&AI$1,Base!$G:$G,"<"&AI$2,Base!$V:$V,"<"&$A$2,Base!$V:$V,">"&0,Base!$A:$A,"2026"),"0") -> 3.3428571 | AJ8: =IFERROR(AVERAGEIFS(Base!$V:$V,Base!$J:$J,Scorecard!$A8,Base!$E:$E,">"&AJ$1,Base!$G:$G,"<"&AJ$2,Base!$V:$V,"<"&$A$2,Base!$V:$V,">"&0,Base!$A:$A,"2026"),"0") -> 0 | AK8: =IFERROR(AVERAGEIFS(Base!$V:$V,Base!$J:$J,Scorecard!$A8,Base!$E:$E,">"&AK$1,Base!$G:$G,"<"&AK$2,Base!$V:$V,"<"&$A$2,Base!$V:$V,">"&0,Base!$A:$A,"2026"),"0") -> 0 | AL8: =IFERROR(AVERAGEIFS(Base!$V:$V,Base!$J:$J,Scorecard!$A8,Base!$E:$E,">"&AL$1,Base!$G:$G,"<"&AL$2,Base!$V:$V,"<"&$A$2,Base!$V:$V,">"&0,Base!$A:$A,"2026"),"0") -> 0 | AM8: =IFERROR(AVERAGEIFS(Base!$V:$V,Base!$J:$J,Scorecard!$A8,Base!$E:$E,">"&AM$1,Base!$G:$G,"<"&AM$2,Base!$V:$V,"<"&$A$2,Base!$V:$V,">"&0,Base!$A:$A,"2026"),"0") -> 0 | AN8: =IFERROR(AVERAGEIFS(Base!$V:$V,Base!$J:$J,Scorecard!$A8,Base!$E:$E,">"&AN$1,Base!$G:$G,"<"&AN$2,Base!$V:$V,"<"&$A$2,Base!$V:$V,">"&0,Base!$A:$A,"2026"),"0") -> 0 | ... AR8: =IFERROR(AVERAGEIFS(Base!$V:$V,Base!$J:$J,Scorecard!$A8,Base!$E:$E,">"&AR$1,Base!$G:$G,"<"&AR$2,Base!$V:$V,"<"&$A$2,Base!$V:$V,">"&0,Base!$A:$A,"2026"),"0") -> 0 | AS8: =IFERROR(AVERAGEIF(AG8:AR8,">0",AG8:AR8),"-") -> 3.5938312 | AT8: =IF(AS8="-",0,IF(AS8>Goals!$N$6,Goals!$O$7,IF(AS8>Goals!$N$5,Goals!$O$6,IF(AS8>Goals!$N$4,Goals!$O$5,IF(AS8>Goals!$N$3,Goals!$O$4,IF(AS8>Goals!$N$2,Goals!$O$3,Goals!$O$2)))))) -> 0.8 | AU8: =IFERROR(COUNTIFS(Base!$E:$E,">"&AU$1,Base!$G:$G,"<"&AU$2,Base!$J:$J,Scorecard!$A8,Base!$T:$T,"COMPLETED")/COUNTIFS(Base!$E:$E,">"&AU$1,Base!$E:$E,"<"&AU$2,Base!$J:$J,Scorecard!$A8),"0") -> 0.8245614 | AV8: =IFERROR(COUNTIFS(Base!$E:$E,">"&AV$1,Base!$G:$G,"<"&AV$2,Base!$J:$J,Scorecard!$A8,Base!$T:$T,"COMPLETED")/COUNTIFS(Base!$E:$E,">"&AV$1,Base!$E:$E,"<"&AV$2,Base!$J:$J,Scorecard!$A8),"0") -> 0.89189189 | AW8: =IFERROR(COUNTIFS(Base!$E:$E,">"&AW$1,Base!$G:$G,"<"&AW$2,Base!$J:$J,Scorecard!$A8,Base!$T:$T,"COMPLETED")/COUNTIFS(Base!$E:$E,">"&AW$1,Base!$E:$E,"<"&AW$2,Base!$J:$J,Scorecard!$A8),"0") -> 0.78571429 | AX8: =IFERROR(COUNTIFS(Base!$E:$E,">"&AX$1,Base!$G:$G,"<"&AX$2,Base!$J:$J,Scorecard!$A8,Base!$T:$T,"COMPLETED")/COUNTIFS(Base!$E:$E,">"&AX$1,Base!$E:$E,"<"&AX$2,Base!$J:$J,Scorecard!$A8),"0") -> 0 | AY8: =IFERROR(COUNTIFS(Base!$E:$E,">"&AY$1,Base!$G:$G,"<"&AY$2,Base!$J:$J,Scorecard!$A8,Base!$T:$T,"COMPLETED")/COUNTIFS(Base!$E:$E,">"&AY$1,Base!$E:$E,"<"&AY$2,Base!$J:$J,Scorecard!$A8),"0") -> 0 | AZ8: =IFERROR(COUNTIFS(Base!$E:$E,">"&AZ$1,Base!$G:$G,"<"&AZ$2,Base!$J:$J,Scorecard!$A8,Base!$T:$T,"COMPLETED")/COUNTIFS(Base!$E:$E,">"&AZ$1,Base!$E:$E,"<"&AZ$2,Base!$J:$J,Scorecard!$A8),"0") -> 0 | BA8: =IFERROR(COUNTIFS(Base!$E:$E,">"&BA$1,Base!$G:$G,"<"&BA$2,Base!$J:$J,Scorecard!$A8,Base!$T:$T,"COMPLETED")/COUNTIFS(Base!$E:$E,">"&BA$1,Base!$E:$E,"<"&BA$2,Base!$J:$J,Scorecard!$A8),"0") -> 0 | BB8: =IFERROR(COUNTIFS(Base!$E:$E,">"&BB$1,Base!$G:$G,"<"&BB$2,Base!$J:$J,Scorecard!$A8,Base!$T:$T,"COMPLETED")/COUNTIFS(Base!$E:$E,">"&BB$1,Base!$E:$E,"<"&BB$2,Base!$J:$J,Scorecard!$A8),"0") -> 0 | ... BF8: =IFERROR(COUNTIFS(Base!$E:$E,">"&BF$1,Base!$G:$G,"<"&BF$2,Base!$J:$J,Scorecard!$A8,Base!$T:$T,"COMPLETED")/COUNTIFS(Base!$E:$E,">"&BF$1,Base!$E:$E,"<"&BF$2,Base!$J:$J,Scorecard!$A8),"0") -> 0 | BG8: =IFERROR(AVERAGEIF(AU8:BF8,">0",AU8:BF8),"-") -> 0.83405586 | BH8: =IF(BG8="-",0,IF(BG8<Goals!$Q$6,Goals!$R$7,IF(BG8<Goals!$Q$5,Goals!$R$6,IF(BG8<Goals!$Q$4,Goals!$R$5,IF(BG8<Goals!$Q$3,Goals!$R$4,IF(BG8<Goals!$Q$2,Goals!$R$3,Goals!$R$2)))))) -> 0.6 | BI8: =COUNTIFS(Strikes!$A:$A,Scorecard!$A8,Strikes!$C:$C,">"&Scorecard!BI$1,Strikes!$C:$C,"<"&Scorecard!BI$2) -> 0 | BJ8: =COUNTIFS(Strikes!$A:$A,Scorecard!$A8,Strikes!$C:$C,">"&Scorecard!BJ$1,Strikes!$C:$C,"<"&Scorecard!BJ$2) -> 0 | BK8: =COUNTIFS(Strikes!$A:$A,Scorecard!$A8,Strikes!$C:$C,">"&Scorecard!BK$1,Strikes!$C:$C,"<"&Scorecard!BK$2) -> 0 | BL8: =COUNTIFS(Strikes!$A:$A,Scorecard!$A8,Strikes!$C:$C,">"&Scorecard!BL$1,Strikes!$C:$C,"<"&Scorecard!BL$2) -> 0 | BM8: =COUNTIFS(Strikes!$A:$A,Scorecard!$A8,Strikes!$C:$C,">"&Scorecard!BM$1,Strikes!$C:$C,"<"&Scorecard!BM$2) -> 0 | BN8: =COUNTIFS(Strikes!$A:$A,Scorecard!$A8,Strikes!$C:$C,">"&Scorecard!BN$1,Strikes!$C:$C,"<"&Scorecard!BN$2) -> 0 | BO8: =COUNTIFS(Strikes!$A:$A,Scorecard!$A8,Strikes!$C:$C,">"&Scorecard!BO$1,Strikes!$C:$C,"<"&Scorecard!BO$2) -> 0 | BP8: =COUNTIFS(Strikes!$A:$A,Scorecard!$A8,Strikes!$C:$C,">"&Scorecard!BP$1,Strikes!$C:$C,"<"&Scorecard!BP$2) -> 0 | ... BT8: =COUNTIFS(Strikes!$A:$A,Scorecard!$A8,Strikes!$C:$C,">"&Scorecard!BT$1,Strikes!$C:$C,"<"&Scorecard!BT$2) -> 0 | BU8: =IFERROR(AVERAGEIF(BI8:BT8,">0",BI8:BT8),"0") -> 0 | BV8: =IF(BU8="-",0,IF(BU8=Goals!$H$7,Goals!$I$7,IF(BU8=Goals!$H$6,Goals!$I$6,IF(BU8=Goals!$H$5,Goals!$I$5,IF(BU8=Goals!$H$4,Goals!$I$4,IF(BU8=Goals!$H$3,Goals!$I$3,Goals!$I$2)))))) -> 1.2 | BW8: =IFERROR(COUNTIFS('Survey Q1'!$C:$C,Scorecard!$A8,'Survey Q1'!$F:$F,"1")/O8,"0") -> 0.84615385 | BX8: =IFERROR(COUNTIFS('Survey Q2'!$C:$C,Scorecard!$A8,'Survey Q1'!$F:$F,"1")/P8,"0") -> 0 | BY8: =IFERROR(COUNTIFS('Survey Q3'!$C:$C,Scorecard!$A8,'Survey Q1'!$F:$F,"1")/Q8,"0") -> 0 | BZ8: =IFERROR(COUNTIFS('Survey Q4'!$C:$C,Scorecard!$A8,'Survey Q1'!$F:$F,"1")/R8,"0") -> 0 | CA8: =IFERROR(AVERAGEIF(BW8:BZ8,">0",BW8:BZ8),"-") -> 0.84615385 | CB8: =IF(CA8="-",0,IF(CA8<Goals!$T$6,Goals!$U$7,IF(CA8<Goals!$T$5,Goals!$U$6,IF(CA8<Goals!$T$4,Goals!$U$5,IF(CA8<Goals!$T$3,Goals!$U$4,IF(CA8<Goals!$T$2,Goals!$U$3,Goals!$U$2)))))) -> 0.6 | CC8: =Scorecard!AF8*Goals!$C$3+Scorecard!AT8*Goals!$D$3+Scorecard!BH8*Goals!$E$3+Scorecard!CB8*Goals!$B$3+BV8*Goals!$F$3 -> 0.66
A9: tiaelima | B9: =COUNTIFS('Sellers Pro'!$F:$F,Scorecard!$A9,'Sellers Pro'!$Q:$Q,"<"&Scorecard!B$2,'Sellers Pro'!$O:$O,"1") -> 39 | C9: =COUNTIFS('Sellers Pro'!$F:$F,Scorecard!$A9,'Sellers Pro'!$Q:$Q,"<"&Scorecard!C$2,'Sellers Pro'!$O:$O,"1") -> 40 | D9: =COUNTIFS('Sellers Pro'!$F:$F,Scorecard!$A9,'Sellers Pro'!$Q:$Q,"<"&Scorecard!D$2,'Sellers Pro'!$O:$O,"1") -> 41 | E9: =COUNTIFS('Sellers Pro'!$F:$F,Scorecard!$A9,'Sellers Pro'!$Q:$Q,"<"&Scorecard!E$2,'Sellers Pro'!$O:$O,"1") -> 41 | F9: =COUNTIFS('Sellers Pro'!$F:$F,Scorecard!$A9,'Sellers Pro'!$Q:$Q,"<"&Scorecard!F$2,'Sellers Pro'!$O:$O,"1") -> 41 | G9: =COUNTIFS('Sellers Pro'!$F:$F,Scorecard!$A9,'Sellers Pro'!$Q:$Q,"<"&Scorecard!G$2,'Sellers Pro'!$O:$O,"1") -> 41 | H9: =COUNTIFS('Sellers Pro'!$F:$F,Scorecard!$A9,'Sellers Pro'!$Q:$Q,"<"&Scorecard!H$2,'Sellers Pro'!$O:$O,"1") -> 41 | I9: =COUNTIFS('Sellers Pro'!$F:$F,Scorecard!$A9,'Sellers Pro'!$Q:$Q,"<"&Scorecard!I$2,'Sellers Pro'!$O:$O,"1") -> 41 | ... M9: =COUNTIFS('Sellers Pro'!$F:$F,Scorecard!$A9,'Sellers Pro'!$Q:$Q,"<"&Scorecard!M$2,'Sellers Pro'!$O:$O,"1") -> 41 | N9: =IFERROR(AVERAGEIF(B9:M9,">0",B9:M9),"-") -> 40.75 | O9: =COUNTIFS('Survey Q1'!$G:$G,"="&1,'Survey Q1'!$C:$C,Scorecard!$A9) -> 15 | P9: =COUNTIFS('Survey Q2'!$G:$G,"="&1,'Survey Q1'!$C:$C,Scorecard!$A9) -> 0 | Q9: =COUNTIFS('Survey Q3'!$G:$G,"="&1,'Survey Q1'!$C:$C,Scorecard!$A9) -> 0 | R9: =COUNTIFS('Survey Q4'!$G:$G,"="&1,'Survey Q1'!$C:$C,Scorecard!$A9) -> 0 | S9: =IFERROR(COUNTIFS(Base!$J:$J,Scorecard!$A9,Base!$E:$E,">"&S$1,Base!$E:$E,"<"&S$2,Base!$AH:$AH,"1",Base!$A:$A,"2026")/$N9,"0") -> 0.80981595 | T9: =IFERROR(COUNTIFS(Base!$J:$J,Scorecard!$A9,Base!$E:$E,">"&T$1,Base!$E:$E,"<"&T$2,Base!$AH:$AH,"1",Base!$A:$A,"2026")/$N9,"0") -> 0.66257669 | U9: =IFERROR(COUNTIFS(Base!$J:$J,Scorecard!$A9,Base!$E:$E,">"&U$1,Base!$E:$E,"<"&U$2,Base!$AH:$AH,"1",Base!$A:$A,"2026")/$N9,"0") -> 0.90797546 | V9: =IFERROR(COUNTIFS(Base!$J:$J,Scorecard!$A9,Base!$E:$E,">"&V$1,Base!$E:$E,"<"&V$2,Base!$AH:$AH,"1",Base!$A:$A,"2026")/$N9,"0") -> 0 | W9: =IFERROR(COUNTIFS(Base!$J:$J,Scorecard!$A9,Base!$E:$E,">"&W$1,Base!$E:$E,"<"&W$2,Base!$AH:$AH,"1",Base!$A:$A,"2026")/$N9,"0") -> 0 | X9: =IFERROR(COUNTIFS(Base!$J:$J,Scorecard!$A9,Base!$E:$E,">"&X$1,Base!$E:$E,"<"&X$2,Base!$AH:$AH,"1",Base!$A:$A,"2026")/$N9,"0") -> 0 | Y9: =IFERROR(COUNTIFS(Base!$J:$J,Scorecard!$A9,Base!$E:$E,">"&Y$1,Base!$E:$E,"<"&Y$2,Base!$AH:$AH,"1",Base!$A:$A,"2026")/$N9,"0") -> 0 | Z9: =IFERROR(COUNTIFS(Base!$J:$J,Scorecard!$A9,Base!$E:$E,">"&Z$1,Base!$E:$E,"<"&Z$2,Base!$AH:$AH,"1",Base!$A:$A,"2026")/$N9,"0") -> 0 | ... AD9: =IFERROR(COUNTIFS(Base!$J:$J,Scorecard!$A9,Base!$E:$E,">"&AD$1,Base!$E:$E,"<"&AD$2,Base!$AH:$AH,"1",Base!$A:$A,"2026")/$N9,"0") -> 0 | AE9: =IFERROR(AVERAGEIF(S9:AD9,">0",S9:AD9),"-") -> 0.79345603 | AF9: =IF(AE9="-",0,IF(AE9<Goals!$K$6,Goals!$L$7,IF(AE9<Goals!$K$5,Goals!$L$6,IF(AE9<Goals!$K$4,Goals!$L$5,IF(AE9<Goals!$K$3,Goals!$L$4,IF(AE9<Goals!$K$2,Goals!$L$3,Goals!$L$2)))))) -> 0.8 | AG9: =IFERROR(AVERAGEIFS(Base!$V:$V,Base!$J:$J,Scorecard!$A9,Base!$E:$E,">"&AG$1,Base!$G:$G,"<"&AG$2,Base!$V:$V,"<"&$A$2,Base!$V:$V,">"&0,Base!$A:$A,"2026"),"0") -> 2.304 | AH9: =IFERROR(AVERAGEIFS(Base!$V:$V,Base!$J:$J,Scorecard!$A9,Base!$E:$E,">"&AH$1,Base!$G:$G,"<"&AH$2,Base!$V:$V,"<"&$A$2,Base!$V:$V,">"&0,Base!$A:$A,"2026"),"0") -> 3.443299 | AI9: =IFERROR(AVERAGEIFS(Base!$V:$V,Base!$J:$J,Scorecard!$A9,Base!$E:$E,">"&AI$1,Base!$G:$G,"<"&AI$2,Base!$V:$V,"<"&$A$2,Base!$V:$V,">"&0,Base!$A:$A,"2026"),"0") -> 2.36 | AJ9: =IFERROR(AVERAGEIFS(Base!$V:$V,Base!$J:$J,Scorecard!$A9,Base!$E:$E,">"&AJ$1,Base!$G:$G,"<"&AJ$2,Base!$V:$V,"<"&$A$2,Base!$V:$V,">"&0,Base!$A:$A,"2026"),"0") -> 0 | AK9: =IFERROR(AVERAGEIFS(Base!$V:$V,Base!$J:$J,Scorecard!$A9,Base!$E:$E,">"&AK$1,Base!$G:$G,"<"&AK$2,Base!$V:$V,"<"&$A$2,Base!$V:$V,">"&0,Base!$A:$A,"2026"),"0") -> 0 | AL9: =IFERROR(AVERAGEIFS(Base!$V:$V,Base!$J:$J,Scorecard!$A9,Base!$E:$E,">"&AL$1,Base!$G:$G,"<"&AL$2,Base!$V:$V,"<"&$A$2,Base!$V:$V,">"&0,Base!$A:$A,"2026"),"0") -> 0 | AM9: =IFERROR(AVERAGEIFS(Base!$V:$V,Base!$J:$J,Scorecard!$A9,Base!$E:$E,">"&AM$1,Base!$G:$G,"<"&AM$2,Base!$V:$V,"<"&$A$2,Base!$V:$V,">"&0,Base!$A:$A,"2026"),"0") -> 0 | AN9: =IFERROR(AVERAGEIFS(Base!$V:$V,Base!$J:$J,Scorecard!$A9,Base!$E:$E,">"&AN$1,Base!$G:$G,"<"&AN$2,Base!$V:$V,"<"&$A$2,Base!$V:$V,">"&0,Base!$A:$A,"2026"),"0") -> 0 | ... AR9: =IFERROR(AVERAGEIFS(Base!$V:$V,Base!$J:$J,Scorecard!$A9,Base!$E:$E,">"&AR$1,Base!$G:$G,"<"&AR$2,Base!$V:$V,"<"&$A$2,Base!$V:$V,">"&0,Base!$A:$A,"2026"),"0") -> 0 | AS9: =IFERROR(AVERAGEIF(AG9:AR9,">0",AG9:AR9),"-") -> 2.702433 | AT9: =IF(AS9="-",0,IF(AS9>Goals!$N$6,Goals!$O$7,IF(AS9>Goals!$N$5,Goals!$O$6,IF(AS9>Goals!$N$4,Goals!$O$5,IF(AS9>Goals!$N$3,Goals!$O$4,IF(AS9>Goals!$N$2,Goals!$O$3,Goals!$O$2)))))) -> 1 | AU9: =IFERROR(COUNTIFS(Base!$E:$E,">"&AU$1,Base!$G:$G,"<"&AU$2,Base!$J:$J,Scorecard!$A9,Base!$T:$T,"COMPLETED")/COUNTIFS(Base!$E:$E,">"&AU$1,Base!$E:$E,"<"&AU$2,Base!$J:$J,Scorecard!$A9),"0") -> 0.85572139 | AV9: =IFERROR(COUNTIFS(Base!$E:$E,">"&AV$1,Base!$G:$G,"<"&AV$2,Base!$J:$J,Scorecard!$A9,Base!$T:$T,"COMPLETED")/COUNTIFS(Base!$E:$E,">"&AV$1,Base!$E:$E,"<"&AV$2,Base!$J:$J,Scorecard!$A9),"0") -> 0.87096774 | AW9: =IFERROR(COUNTIFS(Base!$E:$E,">"&AW$1,Base!$G:$G,"<"&AW$2,Base!$J:$J,Scorecard!$A9,Base!$T:$T,"COMPLETED")/COUNTIFS(Base!$E:$E,">"&AW$1,Base!$E:$E,"<"&AW$2,Base!$J:$J,Scorecard!$A9),"0") -> 0.8 | AX9: =IFERROR(COUNTIFS(Base!$E:$E,">"&AX$1,Base!$G:$G,"<"&AX$2,Base!$J:$J,Scorecard!$A9,Base!$T:$T,"COMPLETED")/COUNTIFS(Base!$E:$E,">"&AX$1,Base!$E:$E,"<"&AX$2,Base!$J:$J,Scorecard!$A9),"0") -> 0 | AY9: =IFERROR(COUNTIFS(Base!$E:$E,">"&AY$1,Base!$G:$G,"<"&AY$2,Base!$J:$J,Scorecard!$A9,Base!$T:$T,"COMPLETED")/COUNTIFS(Base!$E:$E,">"&AY$1,Base!$E:$E,"<"&AY$2,Base!$J:$J,Scorecard!$A9),"0") -> 0 | AZ9: =IFERROR(COUNTIFS(Base!$E:$E,">"&AZ$1,Base!$G:$G,"<"&AZ$2,Base!$J:$J,Scorecard!$A9,Base!$T:$T,"COMPLETED")/COUNTIFS(Base!$E:$E,">"&AZ$1,Base!$E:$E,"<"&AZ$2,Base!$J:$J,Scorecard!$A9),"0") -> 0 | BA9: =IFERROR(COUNTIFS(Base!$E:$E,">"&BA$1,Base!$G:$G,"<"&BA$2,Base!$J:$J,Scorecard!$A9,Base!$T:$T,"COMPLETED")/COUNTIFS(Base!$E:$E,">"&BA$1,Base!$E:$E,"<"&BA$2,Base!$J:$J,Scorecard!$A9),"0") -> 0 | BB9: =IFERROR(COUNTIFS(Base!$E:$E,">"&BB$1,Base!$G:$G,"<"&BB$2,Base!$J:$J,Scorecard!$A9,Base!$T:$T,"COMPLETED")/COUNTIFS(Base!$E:$E,">"&BB$1,Base!$E:$E,"<"&BB$2,Base!$J:$J,Scorecard!$A9),"0") -> 0 | ... BF9: =IFERROR(COUNTIFS(Base!$E:$E,">"&BF$1,Base!$G:$G,"<"&BF$2,Base!$J:$J,Scorecard!$A9,Base!$T:$T,"COMPLETED")/COUNTIFS(Base!$E:$E,">"&BF$1,Base!$E:$E,"<"&BF$2,Base!$J:$J,Scorecard!$A9),"0") -> 0 | BG9: =IFERROR(AVERAGEIF(AU9:BF9,">0",AU9:BF9),"-") -> 0.84222971 | BH9: =IF(BG9="-",0,IF(BG9<Goals!$Q$6,Goals!$R$7,IF(BG9<Goals!$Q$5,Goals!$R$6,IF(BG9<Goals!$Q$4,Goals!$R$5,IF(BG9<Goals!$Q$3,Goals!$R$4,IF(BG9<Goals!$Q$2,Goals!$R$3,Goals!$R$2)))))) -> 0.6 | BI9: =COUNTIFS(Strikes!$A:$A,Scorecard!$A9,Strikes!$C:$C,">"&Scorecard!BI$1,Strikes!$C:$C,"<"&Scorecard!BI$2) -> 0 | BJ9: =COUNTIFS(Strikes!$A:$A,Scorecard!$A9,Strikes!$C:$C,">"&Scorecard!BJ$1,Strikes!$C:$C,"<"&Scorecard!BJ$2) -> 0 | BK9: =COUNTIFS(Strikes!$A:$A,Scorecard!$A9,Strikes!$C:$C,">"&Scorecard!BK$1,Strikes!$C:$C,"<"&Scorecard!BK$2) -> 0 | BL9: =COUNTIFS(Strikes!$A:$A,Scorecard!$A9,Strikes!$C:$C,">"&Scorecard!BL$1,Strikes!$C:$C,"<"&Scorecard!BL$2) -> 0 | BM9: =COUNTIFS(Strikes!$A:$A,Scorecard!$A9,Strikes!$C:$C,">"&Scorecard!BM$1,Strikes!$C:$C,"<"&Scorecard!BM$2) -> 0 | BN9: =COUNTIFS(Strikes!$A:$A,Scorecard!$A9,Strikes!$C:$C,">"&Scorecard!BN$1,Strikes!$C:$C,"<"&Scorecard!BN$2) -> 0 | BO9: =COUNTIFS(Strikes!$A:$A,Scorecard!$A9,Strikes!$C:$C,">"&Scorecard!BO$1,Strikes!$C:$C,"<"&Scorecard!BO$2) -> 0 | BP9: =COUNTIFS(Strikes!$A:$A,Scorecard!$A9,Strikes!$C:$C,">"&Scorecard!BP$1,Strikes!$C:$C,"<"&Scorecard!BP$2) -> 0 | ... BT9: =COUNTIFS(Strikes!$A:$A,Scorecard!$A9,Strikes!$C:$C,">"&Scorecard!BT$1,Strikes!$C:$C,"<"&Scorecard!BT$2) -> 0 | BU9: =IFERROR(AVERAGEIF(BI9:BT9,">0",BI9:BT9),"0") -> 0 | BV9: =IF(BU9="-",0,IF(BU9=Goals!$H$7,Goals!$I$7,IF(BU9=Goals!$H$6,Goals!$I$6,IF(BU9=Goals!$H$5,Goals!$I$5,IF(BU9=Goals!$H$4,Goals!$I$4,IF(BU9=Goals!$H$3,Goals!$I$3,Goals!$I$2)))))) -> 1.2 | BW9: =IFERROR(COUNTIFS('Survey Q1'!$C:$C,Scorecard!$A9,'Survey Q1'!$F:$F,"1")/O9,"0") -> 0.86666667 | BX9: =IFERROR(COUNTIFS('Survey Q2'!$C:$C,Scorecard!$A9,'Survey Q1'!$F:$F,"1")/P9,"0") -> 0 | BY9: =IFERROR(COUNTIFS('Survey Q3'!$C:$C,Scorecard!$A9,'Survey Q1'!$F:$F,"1")/Q9,"0") -> 0 | BZ9: =IFERROR(COUNTIFS('Survey Q4'!$C:$C,Scorecard!$A9,'Survey Q1'!$F:$F,"1")/R9,"0") -> 0 | CA9: =IFERROR(AVERAGEIF(BW9:BZ9,">0",BW9:BZ9),"-") -> 0.86666667 | CB9: =IF(CA9="-",0,IF(CA9<Goals!$T$6,Goals!$U$7,IF(CA9<Goals!$T$5,Goals!$U$6,IF(CA9<Goals!$T$4,Goals!$U$5,IF(CA9<Goals!$T$3,Goals!$U$4,IF(CA9<Goals!$T$2,Goals!$U$3,Goals!$U$2)))))) -> 0.8 | CC9: =Scorecard!AF9*Goals!$C$3+Scorecard!AT9*Goals!$D$3+Scorecard!BH9*Goals!$E$3+Scorecard!CB9*Goals!$B$3+BV9*Goals!$F$3 -> 0.81
A10: wallmach | B10: =COUNTIFS('Sellers Pro'!$F:$F,Scorecard!$A10,'Sellers Pro'!$Q:$Q,"<"&Scorecard!B$2,'Sellers Pro'!$O:$O,"1") -> 33 | C10: =COUNTIFS('Sellers Pro'!$F:$F,Scorecard!$A10,'Sellers Pro'!$Q:$Q,"<"&Scorecard!C$2,'Sellers Pro'!$O:$O,"1") -> 33 | D10: =COUNTIFS('Sellers Pro'!$F:$F,Scorecard!$A10,'Sellers Pro'!$Q:$Q,"<"&Scorecard!D$2,'Sellers Pro'!$O:$O,"1") -> 40 | E10: =COUNTIFS('Sellers Pro'!$F:$F,Scorecard!$A10,'Sellers Pro'!$Q:$Q,"<"&Scorecard!E$2,'Sellers Pro'!$O:$O,"1") -> 40 | F10: =COUNTIFS('Sellers Pro'!$F:$F,Scorecard!$A10,'Sellers Pro'!$Q:$Q,"<"&Scorecard!F$2,'Sellers Pro'!$O:$O,"1") -> 40 | G10: =COUNTIFS('Sellers Pro'!$F:$F,Scorecard!$A10,'Sellers Pro'!$Q:$Q,"<"&Scorecard!G$2,'Sellers Pro'!$O:$O,"1") -> 40 | H10: =COUNTIFS('Sellers Pro'!$F:$F,Scorecard!$A10,'Sellers Pro'!$Q:$Q,"<"&Scorecard!H$2,'Sellers Pro'!$O:$O,"1") -> 40 | I10: =COUNTIFS('Sellers Pro'!$F:$F,Scorecard!$A10,'Sellers Pro'!$Q:$Q,"<"&Scorecard!I$2,'Sellers Pro'!$O:$O,"1") -> 40 | ... M10: =COUNTIFS('Sellers Pro'!$F:$F,Scorecard!$A10,'Sellers Pro'!$Q:$Q,"<"&Scorecard!M$2,'Sellers Pro'!$O:$O,"1") -> 40 | N10: =IFERROR(AVERAGEIF(B10:M10,">0",B10:M10),"-") -> 38.833333 | O10: =COUNTIFS('Survey Q1'!$G:$G,"="&1,'Survey Q1'!$C:$C,Scorecard!$A10) -> 0 | P10: =COUNTIFS('Survey Q2'!$G:$G,"="&1,'Survey Q1'!$C:$C,Scorecard!$A10) -> 0 | Q10: =COUNTIFS('Survey Q3'!$G:$G,"="&1,'Survey Q1'!$C:$C,Scorecard!$A10) -> 0 | R10: =COUNTIFS('Survey Q4'!$G:$G,"="&1,'Survey Q1'!$C:$C,Scorecard!$A10) -> 0 | S10: =IFERROR(COUNTIFS(Base!$J:$J,Scorecard!$A10,Base!$E:$E,">"&S$1,Base!$E:$E,"<"&S$2,Base!$AH:$AH,"1",Base!$A:$A,"2026")/$N10,"0") -> 0 | T10: =IFERROR(COUNTIFS(Base!$J:$J,Scorecard!$A10,Base!$E:$E,">"&T$1,Base!$E:$E,"<"&T$2,Base!$AH:$AH,"1",Base!$A:$A,"2026")/$N10,"0") -> 0 | U10: =IFERROR(COUNTIFS(Base!$J:$J,Scorecard!$A10,Base!$E:$E,">"&U$1,Base!$E:$E,"<"&U$2,Base!$AH:$AH,"1",Base!$A:$A,"2026")/$N10,"0") -> 0 | V10: =IFERROR(COUNTIFS(Base!$J:$J,Scorecard!$A10,Base!$E:$E,">"&V$1,Base!$E:$E,"<"&V$2,Base!$AH:$AH,"1",Base!$A:$A,"2026")/$N10,"0") -> 0 | W10: =IFERROR(COUNTIFS(Base!$J:$J,Scorecard!$A10,Base!$E:$E,">"&W$1,Base!$E:$E,"<"&W$2,Base!$AH:$AH,"1",Base!$A:$A,"2026")/$N10,"0") -> 0 | X10: =IFERROR(COUNTIFS(Base!$J:$J,Scorecard!$A10,Base!$E:$E,">"&X$1,Base!$E:$E,"<"&X$2,Base!$AH:$AH,"1",Base!$A:$A,"2026")/$N10,"0") -> 0 | Y10: =IFERROR(COUNTIFS(Base!$J:$J,Scorecard!$A10,Base!$E:$E,">"&Y$1,Base!$E:$E,"<"&Y$2,Base!$AH:$AH,"1",Base!$A:$A,"2026")/$N10,"0") -> 0 | Z10: =IFERROR(COUNTIFS(Base!$J:$J,Scorecard!$A10,Base!$E:$E,">"&Z$1,Base!$E:$E,"<"&Z$2,Base!$AH:$AH,"1",Base!$A:$A,"2026")/$N10,"0") -> 0 | ... AD10: =IFERROR(COUNTIFS(Base!$J:$J,Scorecard!$A10,Base!$E:$E,">"&AD$1,Base!$E:$E,"<"&AD$2,Base!$AH:$AH,"1",Base!$A:$A,"2026")/$N10,"0") -> 0 | AE10: =IFERROR(AVERAGEIF(S10:AD10,">0",S10:AD10),"-") -> - | AF10: =IF(AE10="-",0,IF(AE10<Goals!$K$6,Goals!$L$7,IF(AE10<Goals!$K$5,Goals!$L$6,IF(AE10<Goals!$K$4,Goals!$L$5,IF(AE10<Goals!$K$3,Goals!$L$4,IF(AE10<Goals!$K$2,Goals!$L$3,Goals!$L$2)))))) -> 0 | AG10: =IFERROR(AVERAGEIFS(Base!$V:$V,Base!$J:$J,Scorecard!$A10,Base!$E:$E,">"&AG$1,Base!$G:$G,"<"&AG$2,Base!$V:$V,"<"&$A$2,Base!$V:$V,">"&0,Base!$A:$A,"2026"),"0") -> 0 | AH10: =IFERROR(AVERAGEIFS(Base!$V:$V,Base!$J:$J,Scorecard!$A10,Base!$E:$E,">"&AH$1,Base!$G:$G,"<"&AH$2,Base!$V:$V,"<"&$A$2,Base!$V:$V,">"&0,Base!$A:$A,"2026"),"0") -> 0 | AI10: =IFERROR(AVERAGEIFS(Base!$V:$V,Base!$J:$J,Scorecard!$A10,Base!$E:$E,">"&AI$1,Base!$G:$G,"<"&AI$2,Base!$V:$V,"<"&$A$2,Base!$V:$V,">"&0,Base!$A:$A,"2026"),"0") -> 0 | AJ10: =IFERROR(AVERAGEIFS(Base!$V:$V,Base!$J:$J,Scorecard!$A10,Base!$E:$E,">"&AJ$1,Base!$G:$G,"<"&AJ$2,Base!$V:$V,"<"&$A$2,Base!$V:$V,">"&0,Base!$A:$A,"2026"),"0") -> 0 | AK10: =IFERROR(AVERAGEIFS(Base!$V:$V,Base!$J:$J,Scorecard!$A10,Base!$E:$E,">"&AK$1,Base!$G:$G,"<"&AK$2,Base!$V:$V,"<"&$A$2,Base!$V:$V,">"&0,Base!$A:$A,"2026"),"0") -> 0 | AL10: =IFERROR(AVERAGEIFS(Base!$V:$V,Base!$J:$J,Scorecard!$A10,Base!$E:$E,">"&AL$1,Base!$G:$G,"<"&AL$2,Base!$V:$V,"<"&$A$2,Base!$V:$V,">"&0,Base!$A:$A,"2026"),"0") -> 0 | AM10: =IFERROR(AVERAGEIFS(Base!$V:$V,Base!$J:$J,Scorecard!$A10,Base!$E:$E,">"&AM$1,Base!$G:$G,"<"&AM$2,Base!$V:$V,"<"&$A$2,Base!$V:$V,">"&0,Base!$A:$A,"2026"),"0") -> 0 | AN10: =IFERROR(AVERAGEIFS(Base!$V:$V,Base!$J:$J,Scorecard!$A10,Base!$E:$E,">"&AN$1,Base!$G:$G,"<"&AN$2,Base!$V:$V,"<"&$A$2,Base!$V:$V,">"&0,Base!$A:$A,"2026"),"0") -> 0 | ... AR10: =IFERROR(AVERAGEIFS(Base!$V:$V,Base!$J:$J,Scorecard!$A10,Base!$E:$E,">"&AR$1,Base!$G:$G,"<"&AR$2,Base!$V:$V,"<"&$A$2,Base!$V:$V,">"&0,Base!$A:$A,"2026"),"0") -> 0 | AS10: =IFERROR(AVERAGEIF(AG10:AR10,">0",AG10:AR10),"-") -> - | AT10: =IF(AS10="-",0,IF(AS10>Goals!$N$6,Goals!$O$7,IF(AS10>Goals!$N$5,Goals!$O$6,IF(AS10>Goals!$N$4,Goals!$O$5,IF(AS10>Goals!$N$3,Goals!$O$4,IF(AS10>Goals!$N$2,Goals!$O$3,Goals!$O$2)))))) -> 0 | AU10: =IFERROR(COUNTIFS(Base!$E:$E,">"&AU$1,Base!$G:$G,"<"&AU$2,Base!$J:$J,Scorecard!$A10,Base!$T:$T,"COMPLETED")/COUNTIFS(Base!$E:$E,">"&AU$1,Base!$E:$E,"<"&AU$2,Base!$J:$J,Scorecard!$A10),"0") -> 0 | AV10: =IFERROR(COUNTIFS(Base!$E:$E,">"&AV$1,Base!$G:$G,"<"&AV$2,Base!$J:$J,Scorecard!$A10,Base!$T:$T,"COMPLETED")/COUNTIFS(Base!$E:$E,">"&AV$1,Base!$E:$E,"<"&AV$2,Base!$J:$J,Scorecard!$A10),"0") -> 0 | AW10: =IFERROR(COUNTIFS(Base!$E:$E,">"&AW$1,Base!$G:$G,"<"&AW$2,Base!$J:$J,Scorecard!$A10,Base!$T:$T,"COMPLETED")/COUNTIFS(Base!$E:$E,">"&AW$1,Base!$E:$E,"<"&AW$2,Base!$J:$J,Scorecard!$A10),"0") -> 0 | AX10: =IFERROR(COUNTIFS(Base!$E:$E,">"&AX$1,Base!$G:$G,"<"&AX$2,Base!$J:$J,Scorecard!$A10,Base!$T:$T,"COMPLETED")/COUNTIFS(Base!$E:$E,">"&AX$1,Base!$E:$E,"<"&AX$2,Base!$J:$J,Scorecard!$A10),"0") -> 0 | AY10: =IFERROR(COUNTIFS(Base!$E:$E,">"&AY$1,Base!$G:$G,"<"&AY$2,Base!$J:$J,Scorecard!$A10,Base!$T:$T,"COMPLETED")/COUNTIFS(Base!$E:$E,">"&AY$1,Base!$E:$E,"<"&AY$2,Base!$J:$J,Scorecard!$A10),"0") -> 0 | AZ10: =IFERROR(COUNTIFS(Base!$E:$E,">"&AZ$1,Base!$G:$G,"<"&AZ$2,Base!$J:$J,Scorecard!$A10,Base!$T:$T,"COMPLETED")/COUNTIFS(Base!$E:$E,">"&AZ$1,Base!$E:$E,"<"&AZ$2,Base!$J:$J,Scorecard!$A10),"0") -> 0 | BA10: =IFERROR(COUNTIFS(Base!$E:$E,">"&BA$1,Base!$G:$G,"<"&BA$2,Base!$J:$J,Scorecard!$A10,Base!$T:$T,"COMPLETED")/COUNTIFS(Base!$E:$E,">"&BA$1,Base!$E:$E,"<"&BA$2,Base!$J:$J,Scorecard!$A10),"0") -> 0 | BB10: =IFERROR(COUNTIFS(Base!$E:$E,">"&BB$1,Base!$G:$G,"<"&BB$2,Base!$J:$J,Scorecard!$A10,Base!$T:$T,"COMPLETED")/COUNTIFS(Base!$E:$E,">"&BB$1,Base!$E:$E,"<"&BB$2,Base!$J:$J,Scorecard!$A10),"0") -> 0 | ... BF10: =IFERROR(COUNTIFS(Base!$E:$E,">"&BF$1,Base!$G:$G,"<"&BF$2,Base!$J:$J,Scorecard!$A10,Base!$T:$T,"COMPLETED")/COUNTIFS(Base!$E:$E,">"&BF$1,Base!$E:$E,"<"&BF$2,Base!$J:$J,Scorecard!$A10),"0") -> 0 | BG10: =IFERROR(AVERAGEIF(AU10:BF10,">0",AU10:BF10),"-") -> - | BH10: =IF(BG10="-",0,IF(BG10<Goals!$Q$6,Goals!$R$7,IF(BG10<Goals!$Q$5,Goals!$R$6,IF(BG10<Goals!$Q$4,Goals!$R$5,IF(BG10<Goals!$Q$3,Goals!$R$4,IF(BG10<Goals!$Q$2,Goals!$R$3,Goals!$R$2)))))) -> 0 | BI10: =COUNTIFS(Strikes!$A:$A,Scorecard!$A10,Strikes!$C:$C,">"&Scorecard!BI$1,Strikes!$C:$C,"<"&Scorecard!BI$2) -> 0 | BJ10: =COUNTIFS(Strikes!$A:$A,Scorecard!$A10,Strikes!$C:$C,">"&Scorecard!BJ$1,Strikes!$C:$C,"<"&Scorecard!BJ$2) -> 0 | BK10: =COUNTIFS(Strikes!$A:$A,Scorecard!$A10,Strikes!$C:$C,">"&Scorecard!BK$1,Strikes!$C:$C,"<"&Scorecard!BK$2) -> 0 | BL10: =COUNTIFS(Strikes!$A:$A,Scorecard!$A10,Strikes!$C:$C,">"&Scorecard!BL$1,Strikes!$C:$C,"<"&Scorecard!BL$2) -> 0 | BM10: =COUNTIFS(Strikes!$A:$A,Scorecard!$A10,Strikes!$C:$C,">"&Scorecard!BM$1,Strikes!$C:$C,"<"&Scorecard!BM$2) -> 0 | BN10: =COUNTIFS(Strikes!$A:$A,Scorecard!$A10,Strikes!$C:$C,">"&Scorecard!BN$1,Strikes!$C:$C,"<"&Scorecard!BN$2) -> 0 | BO10: =COUNTIFS(Strikes!$A:$A,Scorecard!$A10,Strikes!$C:$C,">"&Scorecard!BO$1,Strikes!$C:$C,"<"&Scorecard!BO$2) -> 0 | BP10: =COUNTIFS(Strikes!$A:$A,Scorecard!$A10,Strikes!$C:$C,">"&Scorecard!BP$1,Strikes!$C:$C,"<"&Scorecard!BP$2) -> 0 | ... BT10: =COUNTIFS(Strikes!$A:$A,Scorecard!$A10,Strikes!$C:$C,">"&Scorecard!BT$1,Strikes!$C:$C,"<"&Scorecard!BT$2) -> 0 | BU10: =IFERROR(AVERAGEIF(BI10:BT10,">0",BI10:BT10),"0") -> 0 | BV10: =IF(BU10="-",0,IF(BU10=Goals!$H$7,Goals!$I$7,IF(BU10=Goals!$H$6,Goals!$I$6,IF(BU10=Goals!$H$5,Goals!$I$5,IF(BU10=Goals!$H$4,Goals!$I$4,IF(BU10=Goals!$H$3,Goals!$I$3,Goals!$I$2)))))) -> 1.2 | BW10: =IFERROR(COUNTIFS('Survey Q1'!$C:$C,Scorecard!$A10,'Survey Q1'!$F:$F,"1")/O10,"0") -> 0 | BX10: =IFERROR(COUNTIFS('Survey Q2'!$C:$C,Scorecard!$A10,'Survey Q1'!$F:$F,"1")/P10,"0") -> 0 | BY10: =IFERROR(COUNTIFS('Survey Q3'!$C:$C,Scorecard!$A10,'Survey Q1'!$F:$F,"1")/Q10,"0") -> 0 | BZ10: =IFERROR(COUNTIFS('Survey Q4'!$C:$C,Scorecard!$A10,'Survey Q1'!$F:$F,"1")/R10,"0") -> 0 | CA10: =IFERROR(AVERAGEIF(BW10:BZ10,">0",BW10:BZ10),"-") -> - | CB10: =IF(CA10="-",0,IF(CA10<Goals!$T$6,Goals!$U$7,IF(CA10<Goals!$T$5,Goals!$U$6,IF(CA10<Goals!$T$4,Goals!$U$5,IF(CA10<Goals!$T$3,Goals!$U$4,IF(CA10<Goals!$T$2,Goals!$U$3,Goals!$U$2)))))) -> 0 | CC10: =Scorecard!AF10*Goals!$C$3+Scorecard!AT10*Goals!$D$3+Scorecard!BH10*Goals!$E$3+Scorecard!CB10*Goals!$B$3+BV10*Goals!$F$3 -> 0.06

Sheet Goals
B1: SP Satisfaction (20%) | C1: Growth Levers (80%) | H1: Strikes SOPs | I1: Score | K1: Adoption | L1: Score | N1: TTR (dias) | O1: Score | Q1: % Issue Solved | R1: Score | T1: Seller Satisfaction | U1: Score | V1: Legenda | W1: Score
B2: Survey | C2: Adoption | D2: TTR | E2: Issue % | F2: SOP Strikes | H2: 0 | I2: 1.2 | K2: 0.9 | L2: 1.2 | N2: 1 | O2: 1.2 | Q2: 0.98 | R2: 1.2 | T2: 0.95 | U2: 1.2 | V2: Muito Satisfeito | W2: 1
B3: 0.2 | C3: 0.2 | D3: 0.25 | E3: 0.3 | F3: 0.05 | H3: 2 | I3: 1 | K3: 0.8 | L3: 1 | N3: 3 | O3: 1 | Q3: 0.95 | R3: 1 | T3: 0.9 | U3: 1 | V3: Satisfeto
H4: 4 | I4: 0.8 | K4: 0.7 | L4: 0.8 | N4: 4 | O4: 0.8 | Q4: 0.85 | R4: 0.8 | T4: 0.85 | U4: 0.8 | V4: Nem satisfeito, nem insatisfeito | W4: 0
H5: 6 | I5: 0.6 | K5: 0.7 | L5: 0.6 | N5: 5 | O5: 0.6 | Q5: 0.75 | R5: 0.6 | T5: 0.8 | U5: 0.6 | V5: Insatisfeito
H6: 7 | I6: 0.4 | K6: 0.5 | L6: 0.5 | N6: 6 | O6: 0.5 | Q6: 0.65 | R6: 0.5 | T6: 0.75 | U6: 0.5 | V6: Muito insatisfeito
H7: 8 | I7: 0 | K7: <50% | L7: 0 | N7: 7 | O7: 0 | Q7: <65% | R7: 0 | T7: <75% | U7: 0
H9: SOP Description
H10: Exemplo 1 Descrição: Unidades não recebidas no CD 1/jan: Issue recebido 2/jan: Ticket aberto para o time de FBA --> Link 7/jan: Ticket fechado sem resolução. Thread criada no e-mail pelo Vini 10/jan: Resolução concluída Exemplo 2 Descrição: ASIN bloqueado por HAZMAT 10/jan: Issue recebido 11/jan: Solicitação ao seller das fotos do produto 16/jan: Issue concluído como PSA. Sem retorno do vendedor.
H11: SOP Message
H12: Olá, [ESPAÇO PARA O COLABORADOR ADICIONAR A MENSAGEM PERSONALIZADA] Além disso, segue atualização sobre seus casos em aberto conosco: CASOS EM ACOMPANHAMENTO: 1. KYC Descrição: Problemas de permissão de usuário, não consegue atribuir as permissões ou realizar a verificação de... Status: Em Andamento Última atualização: [colaborador deve adicionar a última atualização do problema] Qualquer dúvida sobre os outros casos, fique à vontade para perguntar! Atenciosamente, [Nome do Colaborador]

Sheet Goal Description
A1: Type | B1: Goal Summary | C1: Timeframe | D1: Weight | E1: Capped | F1: Formula | G1: Definition | H1: Data Source
A2: OMSX Score | B2: 90% OM satisfaction | C2: Quarterly | D2: 0.2 | E2: Yes, 120% | F2: 90% OM satisfaction of SPs that answered survey | G2: Count of SPs that answered with somewhat or extremely satisfied (MC) count in SPX Survey. Eligible 3rd month of program. | H2: Qualtrics
A3: Adoption | B3: 80% of seller adoption | C3: Monthly | D3: 0.2 | E3: Yes, 120% | F3: 80% of seller who are using the program monthly | G3: OMs must have an average of 80% of adoption monthly. This includes proactive tasks | H3: Monthly datanet
A4: TTR (dias) | B4: 3 days | C4: Monthly | D4: 0.25 | E4: Yes, 120% | F4: Average of 3 days in solving tickets | G4: OMs must have an average of 3 days of solved tickets. This formula uses tickets closed in the month related to the metric. Also outliers formulas are being used: Interquartil method and issues solved in more than 0 days are outliers. Proactive tasks included | H4: Monthly datanet
A5: % Issue Solved | B5: 95% issues solved | C5: Monthly | D5: 0.3 | E5: Yes, 120% | F5: Average of 95% of tickets solved monthly | G5: OMs must have an average of 95% of issues solved monthly. This includes proactive tasks. Only tasks resolved in the same month as the creation | H5: Monthly datanet
A6: SOPs followed | B6: SOP followed 100% of the time | C6: Monthly | D6: 0.05 | E6: Yes, 120% | F6: Use the SOPs (issue description and issues status to sellers). | G6: Use the SOPs (issue description and issues status to sellers) everytime. If SOP not used, a strike will be posted in the tracker quip. PM will look weekly 3 sellers per OM and will check wheter there is a strike. At least one message using SOP per day | H6: Quip

Sheet Strikes
A1: Alias | B1: Seller | C1: Data
A2: tiaelima | B2: Webfones | C2: 45810
A3: fpereluc | B3: Avant SP | C3: 45810
A4: qmanuelv | B4: CenterSport | C4: 45810
A5: qmanuelv | B5: FRIGELAR | C5: 45810
A6: gomrodrd | B6: Nespresso | C6: 46080

Sheet Survey Q1
A2: Parent CID | B2: Group | C2: OM | D2: IR Eligible | E2: IR User | F2: Nota Satisfaction | G2: Respondeu | H2: Submission ID | I2: Submitted On | J2: Internal Tags | K2: 1) Digite o nome da sua conta na Amazon. | L2: 2) Digite o seu código de vendedor da Amazon. (Encontre seu código de vendedor [aqui](https://sellercentral.amazon.com.br/sw/AccountInfo/MerchantToken/step/MerchantToken?ref_=macs_aimertok_cont_acinfohm)). | M2: 3) Qual seu nome completo? | N2: 4) Qual seu e-mail? | O2: 5) A sua conta na Amazon é majoritariamente: | P2: 1) Nos últimos 3 meses, quão satisfeito você esteve em vender na Amazon.com.br? | Q2: 2) Nos últimos três meses, quão satisfeito você esteve com o programa de Consultoria Estratégica - SAS? | R2: 3) Em que medida está de acordo com a seguinte afirmação: participar do programa de Consultoria Estratégica (SAS) me ajuda a crescer o meu negócio. | S2: 4) Em que medida está de acordo com a seguinte afirmação: o programa de Consultoria Estratégica (SAS) tem um bom custo benefício. | T2: 5) Quão importante os serviços abaixo oferecidos pelo programa de Consultoria Estratégica (SAS) são para você como vendedor? | U2: 6) Você tem alguma sugestão de como o programa SAS pode melhorar os nossos serviços (seleção, ads, marca, conversão, logística, promoções, resolução de problemas)? | V2: 1) Quem foi o consultor que te atendeu a maior parte do tempo nos últimos 3 meses? | W2: 2) Nos últimos três meses, quão satisfeito você esteve com o seu consultor de marketplace? | X2: 3) Baseado nos últimos três meses de serviço, o quanto você concorda ou não com as afirmações abaixo a respeito do seu consultor de marketplace? | Y2: 4) Você tem alguma sugestão de como o seu consultor pode melhorar o seu atendimento (comunicação, expertise, agilidade, plano de negócios, recomendações, suporte com a conta)? | Z2: 1) Você utiliza a página exclusiva de [Serviços Premium](http://sellercentral.amazon.com.br/gc/sas/servicos-premium)? | AA2: 2) Quão satisfeito você está com o serviço prestado? | AB2: 3) Você tem alguma sugestão de como podemos melhorar sua experiência (adicionar novas tarefas, melhorar o serviço, etc)? | AC2: 1) Você faz parte do programa da Consultoria Estratégica Amazon Select? | AD2: 2) Quão satisfeito você está com o suporte para resolução de problemas operacionais oferecido pelo [Suporte Premium](http://sellercentral.amazon.com.br/gc/sas/suporte-premium)? | AE2: 3) Tem algum feedback adicional a respeito do suporte com a resolução de problemas que você gostaria de compartilhar? | AF2: 1) Você possui um consultor específico para Amazon Ads? | AG2: 2) Quão satisfeito você está com o seu consultor de Amazon Ads? | AH2: 3) Você tem alguma sugestão de como o especialista em Ads que atende sua conta pode melhorar o seu atendimento? | AI2: 1) Por favor, classifique em ordem de importância os módulos do nosso serviço em SAS, sendo 1 o mais importante e 7 o menos importante | AJ2: 2) Quais relatórios você gostaria que a gente implementasse? Coloque em ordem de prioridade. | AK2: QuÃ£o importante os serviÃ§os abaixo oferecidos pelo programa de gerenciamento pago (SAS) sÃ£o para vocÃª como vendedor? - Gerenciamento e suporte de catÃ¡logo | AL2: QuÃ£o importante os serviÃ§os abaixo oferecidos pelo programa de gerenciamento pago (SAS) sÃ£o para vocÃª como vendedor? - Suporte com gerenciamento de inventÃ¡rio | AM2: QuÃ£o importante os serviÃ§os abaixo oferecidos pelo programa de gerenciamento pago (SAS) sÃ£o para vocÃª como vendedor? - Suporte com estratÃ©gia para novos produtos | AN2: VocÃª tem alguma sugestÃ£o de como o programa SAS pode melhorar os nossos serviÃ§os (seleÃ§Ã£o, ads, marca, conversÃ£o, logÃ­stica, promoÃ§Ãµes, resoluÃ§Ã£o de problemas)? | AO2: Quem foi o consultor que te atendeu a maior parte do tempo no perÃ­odo de Julho a Setembro de 2025? | AP2: Nos Ãºltimos trÃªs meses, quÃ£o satisfeito vocÃª esteve com o seu consultor de marketplace? | AQ2: Baseado nos Ãºltimos trÃªs meses de serviÃ§o, o quanto vocÃª concorda ou nÃ£o com as afirmaÃ§Ãµes abaixo a respeito do seu consultor de marketplace? - Meu consultor entende do meu negÃ³cio | AR2: Baseado nos Ãºltimos trÃªs meses de serviÃ§o, o quanto vocÃª concorda ou nÃ£o com as afirmaÃ§Ãµes abaixo a respeito do seu consultor de marketplace? - Meu consultor entende as necessidades do meu negÃ³cio com o programa SAS | AS2: Baseado nos Ãºltimos trÃªs meses de serviÃ§o, o quanto vocÃª concorda ou nÃ£o com as afirmaÃ§Ãµes abaixo a respeito do seu consultor de marketplace? - Meu consultor entende sobre a minha categoria de venda | AT2: Baseado nos Ãºltimos trÃªs meses de serviÃ§o, o quanto vocÃª concorda ou nÃ£o com as afirmaÃ§Ãµes abaixo a respeito do seu consultor de marketplace? - Meu consultor fornece recomendaÃ§Ãµes estratÃ©gicas | AU2: Baseado nos Ãºltimos trÃªs meses de serviÃ§o, o quanto vocÃª concorda ou nÃ£o com as afirmaÃ§Ãµes abaixo a respeito do seu consultor de marketplace? - Meu consultor tem conhecimento dos recursos do Seller Central | AV2: Baseado nos Ãºltimos trÃªs meses de serviÃ§o, o quanto vocÃª concorda ou nÃ£o com as afirmaÃ§Ãµes abaixo a respeito do seu consultor de marketplace? - Meu consultor Ã© responsivo via email | AW2: Baseado nos Ãºltimos trÃªs meses de serviÃ§o, o quanto vocÃª concorda ou nÃ£o com as afirmaÃ§Ãµes abaixo a respeito do seu consultor de marketplace? - Meu consultor se comunica por escrito de forma clara | AX2: VocÃª tem alguma sugestÃ£o de como o seu consultor pode melhorar o seu atendimento (comunicaÃ§Ã£o, expertise, agilidade, plano de negÃ³cios, recomendaÃ§Ãµes, suporte com a conta)? | AY2: VocÃª utiliza a pÃ¡gina exclusiva de ServiÃ§os Premium? | AZ2: QuÃ£o satisfeito vocÃª estÃ¡ com o serviÃ§o prestado? | BA2: VocÃª tem alguma sugestÃ£o de como podemos melhorar sua experiÃªncia (adicionar novas tarefas, melhorar o serviÃ§o, etc)? | BB2: VocÃª possui um gerente de contas operacional, responsÃ¡vel apenas pelo suporte com resoluÃ§Ã£o de problemas operacionais? | BC2: QuÃ£o satisfeito vocÃª estÃ¡ com o suporte para resoluÃ§Ã£o de problemas operacionais? | BD2: Tem algum feedback adicional a respeito do suporte com a resoluÃ§Ã£o de problemas que vocÃª gostaria de compartilhar? | BE2: VocÃª possui um consultor especÃ­fico para Amazon Ads? | BF2: QuÃ£o satisfeito vocÃª estÃ¡ com o seu consultor de Amazon Ads? | BG2: VocÃª tem alguma sugestÃ£o de como o especialista em Ads que atende sua conta pode melhorar o seu atendimento? | BH2: Por favor, classifique em ordem de importÃ¢ncia os mÃ³dulos do nosso serviÃ§o em SAS, sendo 1 o mais importante e 7 o menos importante - SeleÃ§Ã£o (recomendaÃ§Ã£o de produtos, oportunidades) | BI2: Por favor, classifique em ordem de importÃ¢ncia os mÃ³dulos do nosso serviÃ§o em SAS, sendo 1 o mais importante e 7 o menos importante - Advertising (anÃºncios patrocinados) | BJ2: Por favor, classifique em ordem de importÃ¢ncia os mÃ³dulos do nosso serviÃ§o em SAS, sendo 1 o mais importante e 7 o menos importante - Marca (registro, proteÃ§Ã£o, conteÃºdo A+, loja oficial) | BK2: Por favor, classifique em ordem de importÃ¢ncia os mÃ³dulos do nosso serviÃ§o em SAS, sendo 1 o mais importante e 7 o menos importante - ConversÃ£o (qualidade do catÃ¡logo, preÃ§os, listatem) | BL2: Por favor, classifique em ordem de importÃ¢ncia os mÃ³dulos do nosso serviÃ§o em SAS, sendo 1 o mais importante e 7 o menos importante - PromoÃ§Ãµes (ofertas, cupons, eventos) | BM2: Por favor, classifique em ordem de importÃ¢ncia os mÃ³dulos do nosso serviÃ§o em SAS, sendo 1 o mais importante e 7 o menos importante - Ajuda na resoluÃ§Ã£o de problemas operacionais | BN2: Por favor, classifique em ordem de importÃ¢ncia os mÃ³dulos do nosso serviÃ§o em SAS, sendo 1 o mais importante e 7 o menos importante - LogÃ­stica (FBA, FBAOS, DBA, logÃ­stica prÃ³pria) | BO2: Quais relatÃ³rios vocÃª gostaria que a gente implementasse? Coloque em ordem de prioridade. | BP2: Q_DataPolicyViolations
